[2025-05-13 00:39:31] INFO: Używanie najnowszego modelu: D:\python\veteye2\checkpoints\usg_pregnancy_model_inceptionv3_380x380_final.keras
[2025-05-13 00:39:31] INFO: Uruchomiono interfejs analizy obrazów USG
[2025-05-13 00:39:31] INFO: Ładowanie modelu wykrywania ciąży: D:\python\veteye2\checkpoints\usg_pregnancy_model_inceptionv3_380x380_final.keras
[2025-05-13 00:39:34] SUKCES: Model wykrywania ciąży załadowany pomyślnie
[2025-05-13 00:39:34] BŁĄD: Nie znaleziono modelu szacowania dnia ciąży
D:\python\veteye2\logs\training_log_2025-05-13.txt
NoneType: None

[2025-05-13 00:42:14] INFO: Używanie najnowszego modelu: D:\python\veteye2\checkpoints\usg_pregnancy_model_inceptionv3_380x380_final.keras
[2025-05-13 00:42:14] INFO: Uruchomiono interfejs analizy obrazów USG
[2025-05-13 00:42:14] INFO: Ładowanie modelu wykrywania ciąży: D:\python\veteye2\checkpoints\usg_pregnancy_model_inceptionv3_380x380_final.keras
[2025-05-13 00:42:17] SUKCES: Model wykrywania ciąży załadowany pomyślnie
[2025-05-13 00:42:17] BŁĄD: Nie znaleziono modelu szacowania dnia ciąży
D:\python\veteye2\logs\training_log_2025-05-13.txt
NoneType: None

[2025-05-13 00:54:58] INFO: Używanie najnowszego modelu: D:\python\veteye2\checkpoints\usg_pregnancy_model_inceptionv3_380x380_final.keras
[2025-05-13 00:54:58] INFO: Uruchomiono interfejs analizy obrazów USG
[2025-05-13 00:54:58] INFO: Ładowanie modelu wykrywania ciąży: D:\python\veteye2\checkpoints\usg_pregnancy_model_inceptionv3_380x380_final.keras
[2025-05-13 00:55:01] SUKCES: Model wykrywania ciąży załadowany pomyślnie
[2025-05-13 00:55:01] BŁĄD: Nie znaleziono modelu szacowania dnia ciąży
D:\python\veteye2\logs\training_log_2025-05-13.txt
NoneType: None

[2025-05-13 00:59:12] INFO: Używanie najnowszego modelu: D:\python\veteye2\checkpoints\usg_pregnancy_model_inceptionv3_380x380_final.keras
[2025-05-13 00:59:12] INFO: Uruchomiono interfejs analizy obrazów USG
[2025-05-13 00:59:12] INFO: Ładowanie modelu wykrywania ciąży: D:\python\veteye2\checkpoints\usg_pregnancy_model_inceptionv3_380x380_final.keras
[2025-05-13 00:59:14] SUKCES: Model wykrywania ciąży załadowany pomyślnie
[2025-05-13 00:59:14] BŁĄD: Nie znaleziono modelu szacowania dnia ciąży
D:\python\veteye2\logs\training_log_2025-05-13.txt
NoneType: None

[2025-05-13 01:07:18] INFO: Używanie najnowszego modelu: D:\python\veteye2\checkpoints\usg_pregnancy_model_inceptionv3_380x380_final.keras
[2025-05-13 01:07:18] INFO: Uruchomiono interfejs analizy obrazów USG
[2025-05-13 01:07:18] INFO: Ładowanie modelu wykrywania ciąży: D:\python\veteye2\checkpoints\usg_pregnancy_model_inceptionv3_380x380_final.keras
[2025-05-13 01:07:20] SUKCES: Model wykrywania ciąży załadowany pomyślnie
[2025-05-13 01:07:20] BŁĄD: Nie znaleziono modelu szacowania dnia ciąży
D:\python\veteye2\logs\training_log_2025-05-13.txt
NoneType: None

[2025-05-13 01:24:28] INFO: Używanie najnowszego modelu: D:\python\veteye2\checkpoints\usg_pregnancy_model_inceptionv3_380x380_final.keras
[2025-05-13 01:24:28] INFO: Uruchomiono interfejs analizy obrazów USG
[2025-05-13 01:24:28] INFO: Ładowanie modelu wykrywania ciąży: D:\python\veteye2\checkpoints\usg_pregnancy_model_inceptionv3_380x380_final.keras
[2025-05-13 01:24:30] SUKCES: Model wykrywania ciąży załadowany pomyślnie
[2025-05-13 01:24:30] BŁĄD: Nie znaleziono modelu szacowania dnia ciąży
D:\python\veteye2\logs\training_log_2025-05-13.txt
NoneType: None

[2025-05-13 01:36:02] INFO: Używanie najnowszego modelu: D:\python\veteye2\checkpoints\usg_pregnancy_model_inceptionv3_380x380_final.keras
[2025-05-13 01:36:02] INFO: Uruchomiono interfejs analizy obrazów USG
[2025-05-13 01:36:02] INFO: Ładowanie modelu wykrywania ciąży: D:\python\veteye2\checkpoints\usg_pregnancy_model_inceptionv3_380x380_final.keras
[2025-05-13 01:36:04] SUKCES: Model wykrywania ciąży załadowany pomyślnie
[2025-05-13 01:36:04] BŁĄD: Nie znaleziono modelu szacowania dnia ciąży
D:\python\veteye2\logs\training_log_2025-05-13.txt
NoneType: None

[2025-05-13 01:38:53] INFO: Używanie najnowszego modelu: D:\python\veteye2\checkpoints\usg_pregnancy_model_inceptionv3_380x380_final.keras
[2025-05-13 01:38:53] INFO: Uruchomiono interfejs analizy obrazów USG
[2025-05-13 01:38:53] INFO: Ładowanie modelu wykrywania ciąży: D:\python\veteye2\checkpoints\usg_pregnancy_model_inceptionv3_380x380_final.keras
[2025-05-13 01:38:55] SUKCES: Model wykrywania ciąży załadowany pomyślnie
[2025-05-13 01:38:55] BŁĄD: Nie znaleziono modelu szacowania dnia ciąży
D:\python\veteye2\logs\training_log_2025-05-13.txt
NoneType: None

[2025-05-13 01:39:29] INFO: Używanie najnowszego modelu: D:\python\veteye2\checkpoints\usg_pregnancy_model_inceptionv3_380x380_final.keras
[2025-05-13 01:39:29] INFO: Uruchomiono interfejs analizy obrazów USG
[2025-05-13 01:39:29] INFO: Ładowanie modelu wykrywania ciąży: D:\python\veteye2\checkpoints\usg_pregnancy_model_inceptionv3_380x380_final.keras
[2025-05-13 01:39:31] SUKCES: Model wykrywania ciąży załadowany pomyślnie
[2025-05-13 01:39:31] BŁĄD: Nie znaleziono modelu szacowania dnia ciąży
D:\python\veteye2\logs\training_log_2025-05-13.txt
NoneType: None

[2025-05-13 01:39:56] INFO: Używanie najnowszego modelu: D:\python\veteye2\checkpoints\usg_pregnancy_model_inceptionv3_380x380_final.keras
[2025-05-13 01:39:56] INFO: Uruchomiono interfejs analizy obrazów USG
[2025-05-13 01:39:56] INFO: Ładowanie modelu wykrywania ciąży: D:\python\veteye2\checkpoints\usg_pregnancy_model_inceptionv3_380x380_final.keras
[2025-05-13 01:39:59] SUKCES: Model wykrywania ciąży załadowany pomyślnie
[2025-05-13 01:39:59] BŁĄD: Nie znaleziono modelu szacowania dnia ciąży
D:\python\veteye2\logs\training_log_2025-05-13.txt
NoneType: None

[2025-05-13 01:52:07] INFO: Używanie najnowszego modelu: D:\python\veteye2\checkpoints\usg_pregnancy_model_inceptionv3_380x380_final.keras
[2025-05-13 01:52:07] INFO: Uruchomiono interfejs analizy obrazów USG
[2025-05-13 01:52:07] INFO: Ładowanie modelu wykrywania ciąży: D:\python\veteye2\checkpoints\usg_pregnancy_model_inceptionv3_380x380_final.keras
[2025-05-13 01:52:09] SUKCES: Model wykrywania ciąży załadowany pomyślnie
[2025-05-13 01:52:09] BŁĄD: Nie znaleziono modelu szacowania dnia ciąży
D:\python\veteye2\logs\training_log_2025-05-13.txt
NoneType: None

[2025-05-13 01:52:24] BŁĄD: Błąd predykcji: 'sea green' is not a valid color value.
D:\python\veteye2\logs\training_log_2025-05-13.txt
Traceback (most recent call last):
  File "D:\python\veteye2\scripts\analysis_gui.py", line 367, in analyze_current_image
    self.plot_features(image_features)
  File "D:\python\veteye2\scripts\analysis_gui.py", line 216, in plot_features
    bars = ax.barh(labels, values, color='mediumseagreen', edgecolor='sea green')
  File "D:\python\veteye2\veteye2_env\lib\site-packages\matplotlib\axes\_axes.py", line 2812, in barh
    patches = self.bar(x=left, height=height, width=width, bottom=y,
  File "D:\python\veteye2\veteye2_env\lib\site-packages\matplotlib\__init__.py", line 1521, in inner
    return func(
  File "D:\python\veteye2\veteye2_env\lib\site-packages\matplotlib\axes\_axes.py", line 2603, in bar
    itertools.cycle(mcolors.to_rgba_array(edgecolor)),
  File "D:\python\veteye2\veteye2_env\lib\site-packages\matplotlib\colors.py", line 498, in to_rgba_array
    raise ValueError(f"{c!r} is not a valid color value.")
ValueError: 'sea green' is not a valid color value.

[2025-05-13 01:52:52] BŁĄD: Błąd predykcji: 'sea green' is not a valid color value.
D:\python\veteye2\logs\training_log_2025-05-13.txt
Traceback (most recent call last):
  File "D:\python\veteye2\scripts\analysis_gui.py", line 367, in analyze_current_image
    self.plot_features(image_features)
  File "D:\python\veteye2\scripts\analysis_gui.py", line 216, in plot_features
    bars = ax.barh(labels, values, color='mediumseagreen', edgecolor='seagreen')
  File "D:\python\veteye2\veteye2_env\lib\site-packages\matplotlib\axes\_axes.py", line 2812, in barh
    patches = self.bar(x=left, height=height, width=width, bottom=y,
  File "D:\python\veteye2\veteye2_env\lib\site-packages\matplotlib\__init__.py", line 1521, in inner
    return func(
  File "D:\python\veteye2\veteye2_env\lib\site-packages\matplotlib\axes\_axes.py", line 2603, in bar
    itertools.cycle(mcolors.to_rgba_array(edgecolor)),
  File "D:\python\veteye2\veteye2_env\lib\site-packages\matplotlib\colors.py", line 498, in to_rgba_array
    raise ValueError(f"{c!r} is not a valid color value.")
ValueError: 'sea green' is not a valid color value.

[2025-05-13 01:53:04] INFO: Używanie najnowszego modelu: D:\python\veteye2\checkpoints\usg_pregnancy_model_inceptionv3_380x380_final.keras
[2025-05-13 01:53:04] INFO: Uruchomiono interfejs analizy obrazów USG
[2025-05-13 01:53:04] INFO: Ładowanie modelu wykrywania ciąży: D:\python\veteye2\checkpoints\usg_pregnancy_model_inceptionv3_380x380_final.keras
[2025-05-13 01:53:06] SUKCES: Model wykrywania ciąży załadowany pomyślnie
[2025-05-13 01:53:06] BŁĄD: Nie znaleziono modelu szacowania dnia ciąży
D:\python\veteye2\logs\training_log_2025-05-13.txt
NoneType: None

[2025-05-13 01:53:22] INFO: Używanie najnowszego modelu: D:\python\veteye2\checkpoints\usg_pregnancy_model_inceptionv3_380x380_final.keras
[2025-05-13 01:53:22] INFO: Uruchomiono interfejs analizy obrazów USG
[2025-05-13 01:53:22] INFO: Ładowanie modelu wykrywania ciąży: D:\python\veteye2\checkpoints\usg_pregnancy_model_inceptionv3_380x380_final.keras
[2025-05-13 01:53:24] SUKCES: Model wykrywania ciąży załadowany pomyślnie
[2025-05-13 01:53:24] BŁĄD: Nie znaleziono modelu szacowania dnia ciąży
D:\python\veteye2\logs\training_log_2025-05-13.txt
NoneType: None

[2025-05-13 01:58:49] INFO: Używanie najnowszego modelu: D:\python\veteye2\checkpoints\usg_pregnancy_model_inceptionv3_380x380_final.keras
[2025-05-13 01:58:49] INFO: Uruchomiono interfejs analizy obrazów USG
[2025-05-13 01:58:49] INFO: Ładowanie modelu wykrywania ciąży: D:\python\veteye2\checkpoints\usg_pregnancy_model_inceptionv3_380x380_final.keras
[2025-05-13 01:58:51] SUKCES: Model wykrywania ciąży załadowany pomyślnie
[2025-05-13 01:58:51] BŁĄD: Nie znaleziono modelu szacowania dnia ciąży
D:\python\veteye2\logs\training_log_2025-05-13.txt
NoneType: None

[2025-05-13 01:58:57] BŁĄD: Błąd predykcji: ' green' is not a valid color value.
D:\python\veteye2\logs\training_log_2025-05-13.txt
Traceback (most recent call last):
  File "D:\python\veteye2\scripts\analysis_gui.py", line 367, in analyze_current_image
    self.plot_features(image_features)
  File "D:\python\veteye2\scripts\analysis_gui.py", line 216, in plot_features
    bars = ax.barh(labels, values, color='mediumseagreen', edgecolor=' green')
  File "D:\python\veteye2\veteye2_env\lib\site-packages\matplotlib\axes\_axes.py", line 2812, in barh
    patches = self.bar(x=left, height=height, width=width, bottom=y,
  File "D:\python\veteye2\veteye2_env\lib\site-packages\matplotlib\__init__.py", line 1521, in inner
    return func(
  File "D:\python\veteye2\veteye2_env\lib\site-packages\matplotlib\axes\_axes.py", line 2603, in bar
    itertools.cycle(mcolors.to_rgba_array(edgecolor)),
  File "D:\python\veteye2\veteye2_env\lib\site-packages\matplotlib\colors.py", line 498, in to_rgba_array
    raise ValueError(f"{c!r} is not a valid color value.")
ValueError: ' green' is not a valid color value.

[2025-05-13 02:00:09] INFO: Używanie najnowszego modelu: D:\python\veteye2\checkpoints\usg_pregnancy_model_inceptionv3_380x380_final.keras
[2025-05-13 02:00:09] INFO: Uruchomiono interfejs analizy obrazów USG
[2025-05-13 02:00:09] INFO: Ładowanie modelu wykrywania ciąży: D:\python\veteye2\checkpoints\usg_pregnancy_model_inceptionv3_380x380_final.keras
[2025-05-13 02:00:11] SUKCES: Model wykrywania ciąży załadowany pomyślnie
[2025-05-13 02:00:11] BŁĄD: Nie znaleziono modelu szacowania dnia ciąży
D:\python\veteye2\logs\training_log_2025-05-13.txt
NoneType: None

[2025-05-13 02:06:48] INFO: Używanie najnowszego modelu: D:\python\veteye2\checkpoints\usg_pregnancy_model_inceptionv3_380x380_final.keras
[2025-05-13 02:06:48] INFO: Uruchomiono interfejs analizy obrazów USG
[2025-05-13 02:06:48] INFO: Ładowanie modelu wykrywania ciąży: D:\python\veteye2\checkpoints\usg_pregnancy_model_inceptionv3_380x380_final.keras
[2025-05-13 02:06:50] SUKCES: Model wykrywania ciąży załadowany pomyślnie
[2025-05-13 02:06:50] BŁĄD: Nie znaleziono modelu szacowania dnia ciąży
D:\python\veteye2\logs\training_log_2025-05-13.txt
NoneType: None

[2025-05-13 02:07:00] BŁĄD: Błąd generowania raportu: cannot import name 'save_features_plot_to_file' from 'diagnostic_utils' (D:\python\veteye2\scripts\diagnostic_utils.py)
D:\python\veteye2\logs\training_log_2025-05-13.txt
Traceback (most recent call last):
  File "D:\python\veteye2\scripts\analysis_gui.py", line 388, in generate_report
    report_path = generate_pdf_report(
  File "D:\python\veteye2\scripts\diagnostic_utils.py", line 216, in generate_pdf_report
    from diagnostic_utils import save_features_plot_to_file  # jeśli masz w osobnym pliku
ImportError: cannot import name 'save_features_plot_to_file' from 'diagnostic_utils' (D:\python\veteye2\scripts\diagnostic_utils.py)

[2025-05-13 02:13:12] INFO: Używanie najnowszego modelu: D:\python\veteye2\checkpoints\usg_pregnancy_model_inceptionv3_380x380_final.keras
[2025-05-13 02:13:12] INFO: Uruchomiono interfejs analizy obrazów USG
[2025-05-13 02:13:12] INFO: Ładowanie modelu wykrywania ciąży: D:\python\veteye2\checkpoints\usg_pregnancy_model_inceptionv3_380x380_final.keras
[2025-05-13 02:13:14] SUKCES: Model wykrywania ciąży załadowany pomyślnie
[2025-05-13 02:13:14] BŁĄD: Nie znaleziono modelu szacowania dnia ciąży
D:\python\veteye2\logs\training_log_2025-05-13.txt
NoneType: None

[2025-05-13 02:13:22] BŁĄD: Błąd generowania raportu: name 'plt' is not defined
D:\python\veteye2\logs\training_log_2025-05-13.txt
Traceback (most recent call last):
  File "D:\python\veteye2\scripts\analysis_gui.py", line 370, in generate_report
    report_path = generate_pdf_report(
  File "D:\python\veteye2\scripts\diagnostic_utils.py", line 238, in generate_pdf_report
    chart_path = save_features_plot_to_file(image_features)
  File "D:\python\veteye2\scripts\diagnostic_utils.py", line 39, in save_features_plot_to_file
    fig, ax = plt.subplots(figsize=(6, 4))
NameError: name 'plt' is not defined

[2025-05-13 02:14:21] BŁĄD: Błąd generowania raportu: name 'plt' is not defined
D:\python\veteye2\logs\training_log_2025-05-13.txt
Traceback (most recent call last):
  File "D:\python\veteye2\scripts\analysis_gui.py", line 370, in generate_report
    report_path = generate_pdf_report(
  File "D:\python\veteye2\scripts\diagnostic_utils.py", line 238, in generate_pdf_report
  File "D:\python\veteye2\scripts\diagnostic_utils.py", line 39, in save_features_plot_to_file
    def save_features_plot_to_file(image_features):
NameError: name 'plt' is not defined

[2025-05-13 02:14:30] INFO: Używanie najnowszego modelu: D:\python\veteye2\checkpoints\usg_pregnancy_model_inceptionv3_380x380_final.keras
[2025-05-13 02:14:30] INFO: Uruchomiono interfejs analizy obrazów USG
[2025-05-13 02:14:30] INFO: Ładowanie modelu wykrywania ciąży: D:\python\veteye2\checkpoints\usg_pregnancy_model_inceptionv3_380x380_final.keras
[2025-05-13 02:14:33] SUKCES: Model wykrywania ciąży załadowany pomyślnie
[2025-05-13 02:14:33] BŁĄD: Nie znaleziono modelu szacowania dnia ciąży
D:\python\veteye2\logs\training_log_2025-05-13.txt
NoneType: None

[2025-05-13 02:14:40] BŁĄD: Błąd generowania raportu: name 'tempfile' is not defined
D:\python\veteye2\logs\training_log_2025-05-13.txt
Traceback (most recent call last):
  File "D:\python\veteye2\scripts\analysis_gui.py", line 370, in generate_report
    report_path = generate_pdf_report(
  File "D:\python\veteye2\scripts\diagnostic_utils.py", line 239, in generate_pdf_report
    chart_path = save_features_plot_to_file(image_features)
  File "D:\python\veteye2\scripts\diagnostic_utils.py", line 51, in save_features_plot_to_file
    tmp_file = tempfile.NamedTemporaryFile(delete=False, suffix='.png')
NameError: name 'tempfile' is not defined

[2025-05-13 02:15:37] INFO: Używanie najnowszego modelu: D:\python\veteye2\checkpoints\usg_pregnancy_model_inceptionv3_380x380_final.keras
[2025-05-13 02:15:37] INFO: Uruchomiono interfejs analizy obrazów USG
[2025-05-13 02:15:37] INFO: Ładowanie modelu wykrywania ciąży: D:\python\veteye2\checkpoints\usg_pregnancy_model_inceptionv3_380x380_final.keras
[2025-05-13 02:15:39] SUKCES: Model wykrywania ciąży załadowany pomyślnie
[2025-05-13 02:15:39] BŁĄD: Nie znaleziono modelu szacowania dnia ciąży
D:\python\veteye2\logs\training_log_2025-05-13.txt
NoneType: None

[2025-05-13 02:20:30] INFO: Używanie najnowszego modelu: D:\python\veteye2\checkpoints\usg_pregnancy_model_inceptionv3_380x380_final.keras
[2025-05-13 02:20:30] INFO: Uruchomiono interfejs analizy obrazów USG
[2025-05-13 02:20:30] INFO: Ładowanie modelu wykrywania ciąży: D:\python\veteye2\checkpoints\usg_pregnancy_model_inceptionv3_380x380_final.keras
[2025-05-13 02:20:32] SUKCES: Model wykrywania ciąży załadowany pomyślnie
[2025-05-13 02:20:32] BŁĄD: Nie znaleziono modelu szacowania dnia ciąży
D:\python\veteye2\logs\training_log_2025-05-13.txt
NoneType: None

[2025-05-13 02:20:40] BŁĄD: Błąd generowania raportu: name 'Image' is not defined
D:\python\veteye2\logs\training_log_2025-05-13.txt
Traceback (most recent call last):
  File "D:\python\veteye2\scripts\analysis_gui.py", line 370, in generate_report
    report_path = generate_pdf_report(
  File "D:\python\veteye2\scripts\diagnostic_utils.py", line 243, in generate_pdf_report
    story.append(Image(chart_path, width=5.5 * inch, height=3.5 * inch))
NameError: name 'Image' is not defined

[2025-05-13 02:23:00] BŁĄD: Błąd generowania raportu: name 'Image' is not defined
D:\python\veteye2\logs\training_log_2025-05-13.txt
Traceback (most recent call last):
  File "D:\python\veteye2\scripts\analysis_gui.py", line 370, in generate_report
    report_path = generate_pdf_report(
  File "D:\python\veteye2\scripts\diagnostic_utils.py", line 243, in generate_pdf_report
    story.append(ReportLabImage(chart_path, width=5.5 * inch, height=3.5 * inch))
NameError: name 'Image' is not defined

[2025-05-13 02:23:09] INFO: Używanie najnowszego modelu: D:\python\veteye2\checkpoints\usg_pregnancy_model_inceptionv3_380x380_final.keras
[2025-05-13 02:23:10] INFO: Uruchomiono interfejs analizy obrazów USG
[2025-05-13 02:23:10] INFO: Ładowanie modelu wykrywania ciąży: D:\python\veteye2\checkpoints\usg_pregnancy_model_inceptionv3_380x380_final.keras
[2025-05-13 02:23:12] SUKCES: Model wykrywania ciąży załadowany pomyślnie
[2025-05-13 02:23:12] BŁĄD: Nie znaleziono modelu szacowania dnia ciąży
D:\python\veteye2\logs\training_log_2025-05-13.txt
NoneType: None

[2025-05-13 02:28:56] INFO: Używanie najnowszego modelu: D:\python\veteye2\checkpoints\usg_pregnancy_model_inceptionv3_380x380_final.keras
[2025-05-13 02:28:56] INFO: Uruchomiono interfejs analizy obrazów USG
[2025-05-13 02:28:56] INFO: Ładowanie modelu wykrywania ciąży: D:\python\veteye2\checkpoints\usg_pregnancy_model_inceptionv3_380x380_final.keras
[2025-05-13 02:28:58] SUKCES: Model wykrywania ciąży załadowany pomyślnie
[2025-05-13 02:28:58] BŁĄD: Nie znaleziono modelu szacowania dnia ciąży
D:\python\veteye2\logs\training_log_2025-05-13.txt
NoneType: None

[2025-05-13 02:31:50] INFO: Używanie najnowszego modelu: D:\python\veteye2\checkpoints\usg_pregnancy_model_inceptionv3_380x380_final.keras
[2025-05-13 02:31:50] INFO: Uruchomiono interfejs analizy obrazów USG
[2025-05-13 02:31:50] INFO: Ładowanie modelu wykrywania ciąży: D:\python\veteye2\checkpoints\usg_pregnancy_model_inceptionv3_380x380_final.keras
[2025-05-13 02:31:52] SUKCES: Model wykrywania ciąży załadowany pomyślnie
[2025-05-13 02:31:52] BŁĄD: Nie znaleziono modelu szacowania dnia ciąży
D:\python\veteye2\logs\training_log_2025-05-13.txt
NoneType: None

[2025-05-13 02:33:42] INFO: Używanie najnowszego modelu: D:\python\veteye2\checkpoints\usg_pregnancy_model_inceptionv3_380x380_final.keras
[2025-05-13 02:33:42] INFO: Uruchomiono interfejs analizy obrazów USG
[2025-05-13 02:33:42] INFO: Ładowanie modelu wykrywania ciąży: D:\python\veteye2\checkpoints\usg_pregnancy_model_inceptionv3_380x380_final.keras
[2025-05-13 02:33:45] SUKCES: Model wykrywania ciąży załadowany pomyślnie
[2025-05-13 02:33:45] BŁĄD: Nie znaleziono modelu szacowania dnia ciąży
D:\python\veteye2\logs\training_log_2025-05-13.txt
NoneType: None

[2025-05-13 02:35:34] INFO: Używanie najnowszego modelu: D:\python\veteye2\checkpoints\usg_pregnancy_model_inceptionv3_380x380_final.keras
[2025-05-13 02:35:34] INFO: Uruchomiono interfejs analizy obrazów USG
[2025-05-13 02:35:34] INFO: Ładowanie modelu wykrywania ciąży: D:\python\veteye2\checkpoints\usg_pregnancy_model_inceptionv3_380x380_final.keras
[2025-05-13 02:35:36] SUKCES: Model wykrywania ciąży załadowany pomyślnie
[2025-05-13 02:35:36] BŁĄD: Nie znaleziono modelu szacowania dnia ciąży
D:\python\veteye2\logs\training_log_2025-05-13.txt
NoneType: None

[2025-05-13 02:36:10] INFO: Używanie najnowszego modelu: D:\python\veteye2\checkpoints\usg_pregnancy_model_inceptionv3_380x380_final.keras
[2025-05-13 02:36:10] INFO: Uruchomiono interfejs analizy obrazów USG
[2025-05-13 02:36:10] INFO: Ładowanie modelu wykrywania ciąży: D:\python\veteye2\checkpoints\usg_pregnancy_model_inceptionv3_380x380_final.keras
[2025-05-13 02:36:12] SUKCES: Model wykrywania ciąży załadowany pomyślnie
[2025-05-13 02:36:12] BŁĄD: Nie znaleziono modelu szacowania dnia ciąży
D:\python\veteye2\logs\training_log_2025-05-13.txt
NoneType: None

[2025-05-13 02:37:09] INFO: Używanie najnowszego modelu: D:\python\veteye2\checkpoints\usg_pregnancy_model_inceptionv3_380x380_final.keras
[2025-05-13 02:37:09] INFO: Uruchomiono interfejs analizy obrazów USG
[2025-05-13 02:37:09] INFO: Ładowanie modelu wykrywania ciąży: D:\python\veteye2\checkpoints\usg_pregnancy_model_inceptionv3_380x380_final.keras
[2025-05-13 02:37:11] SUKCES: Model wykrywania ciąży załadowany pomyślnie
[2025-05-13 02:37:11] BŁĄD: Nie znaleziono modelu szacowania dnia ciąży
D:\python\veteye2\logs\training_log_2025-05-13.txt
NoneType: None

[2025-05-13 02:38:02] INFO: Używanie najnowszego modelu: D:\python\veteye2\checkpoints\usg_pregnancy_model_inceptionv3_380x380_final.keras
[2025-05-13 02:38:02] INFO: Uruchomiono interfejs analizy obrazów USG
[2025-05-13 02:38:02] INFO: Ładowanie modelu wykrywania ciąży: D:\python\veteye2\checkpoints\usg_pregnancy_model_inceptionv3_380x380_final.keras
[2025-05-13 02:38:05] SUKCES: Model wykrywania ciąży załadowany pomyślnie
[2025-05-13 02:38:05] BŁĄD: Nie znaleziono modelu szacowania dnia ciąży
D:\python\veteye2\logs\training_log_2025-05-13.txt
NoneType: None

[2025-05-13 02:40:11] INFO: Używanie najnowszego modelu: D:\python\veteye2\checkpoints\usg_pregnancy_model_inceptionv3_380x380_final.keras
[2025-05-13 02:40:12] INFO: Uruchomiono interfejs analizy obrazów USG
[2025-05-13 02:40:12] INFO: Ładowanie modelu wykrywania ciąży: D:\python\veteye2\checkpoints\usg_pregnancy_model_inceptionv3_380x380_final.keras
[2025-05-13 02:40:14] SUKCES: Model wykrywania ciąży załadowany pomyślnie
[2025-05-13 02:40:14] BŁĄD: Nie znaleziono modelu szacowania dnia ciąży
D:\python\veteye2\logs\training_log_2025-05-13.txt
NoneType: None

[2025-05-13 02:41:01] INFO: Używanie najnowszego modelu: D:\python\veteye2\checkpoints\usg_pregnancy_model_inceptionv3_380x380_final.keras
[2025-05-13 02:41:01] INFO: Uruchomiono interfejs analizy obrazów USG
[2025-05-13 02:41:01] INFO: Ładowanie modelu wykrywania ciąży: D:\python\veteye2\checkpoints\usg_pregnancy_model_inceptionv3_380x380_final.keras
[2025-05-13 02:41:03] SUKCES: Model wykrywania ciąży załadowany pomyślnie
[2025-05-13 02:41:03] BŁĄD: Nie znaleziono modelu szacowania dnia ciąży
D:\python\veteye2\logs\training_log_2025-05-13.txt
NoneType: None

[2025-05-13 10:54:37] INFO: Używanie najnowszego modelu: D:\PYTHON\veteye2\checkpoints\usg_pregnancy_model_inceptionv3_380x380_final.keras
[2025-05-13 10:54:37] INFO: Uruchomiono interfejs analizy obrazów USG
[2025-05-13 10:54:37] INFO: Ładowanie modelu wykrywania ciąży: D:\PYTHON\veteye2\checkpoints\usg_pregnancy_model_inceptionv3_380x380_final.keras
[2025-05-13 10:54:40] SUKCES: Model wykrywania ciąży załadowany pomyślnie
[2025-05-13 10:54:40] BŁĄD: Nie znaleziono modelu szacowania dnia ciąży
D:\PYTHON\veteye2\logs\training_log_2025-05-13.txt
NoneType: None

[2025-05-13 11:01:02] INFO: Używanie najnowszego modelu: D:\PYTHON\veteye2\checkpoints\usg_pregnancy_model_inceptionv3_380x380_final.keras
[2025-05-13 11:01:02] INFO: Uruchomiono interfejs analizy obrazów USG
[2025-05-13 11:01:02] INFO: Ładowanie modelu wykrywania ciąży: D:\PYTHON\veteye2\checkpoints\usg_pregnancy_model_inceptionv3_380x380_final.keras
[2025-05-13 11:01:04] SUKCES: Model wykrywania ciąży załadowany pomyślnie
[2025-05-13 11:01:04] BŁĄD: Nie znaleziono modelu szacowania dnia ciąży
D:\PYTHON\veteye2\logs\training_log_2025-05-13.txt
NoneType: None

[2025-05-13 11:02:12] INFO: Używanie najnowszego modelu: D:\PYTHON\veteye2\checkpoints\usg_pregnancy_model_inceptionv3_380x380_final.keras
[2025-05-13 11:02:12] INFO: Uruchomiono interfejs analizy obrazów USG
[2025-05-13 11:02:12] INFO: Ładowanie modelu wykrywania ciąży: D:\PYTHON\veteye2\checkpoints\usg_pregnancy_model_inceptionv3_380x380_final.keras
[2025-05-13 11:02:14] SUKCES: Model wykrywania ciąży załadowany pomyślnie
[2025-05-13 11:02:14] BŁĄD: Nie znaleziono modelu szacowania dnia ciąży
D:\PYTHON\veteye2\logs\training_log_2025-05-13.txt
NoneType: None

[2025-05-13 11:04:53] INFO: Używanie najnowszego modelu: D:\PYTHON\veteye2\checkpoints\usg_pregnancy_model_inceptionv3_380x380_final.keras
[2025-05-13 11:04:53] INFO: Uruchomiono interfejs analizy obrazów USG
[2025-05-13 11:04:53] INFO: Ładowanie modelu wykrywania ciąży: D:\PYTHON\veteye2\checkpoints\usg_pregnancy_model_inceptionv3_380x380_final.keras
[2025-05-13 11:04:55] SUKCES: Model wykrywania ciąży załadowany pomyślnie
[2025-05-13 11:04:55] BŁĄD: Nie znaleziono modelu szacowania dnia ciąży
D:\PYTHON\veteye2\logs\training_log_2025-05-13.txt
NoneType: None

[2025-05-13 11:07:29] INFO: Używanie najnowszego modelu: D:\PYTHON\veteye2\checkpoints\usg_pregnancy_model_inceptionv3_380x380_final.keras
[2025-05-13 11:07:29] INFO: Uruchomiono interfejs analizy obrazów USG
[2025-05-13 11:07:59] INFO: Używanie najnowszego modelu: D:\PYTHON\veteye2\checkpoints\usg_pregnancy_model_inceptionv3_380x380_final.keras
[2025-05-13 11:07:59] INFO: Uruchomiono interfejs analizy obrazów USG
[2025-05-13 11:07:59] INFO: Ładowanie modelu wykrywania ciąży: D:\PYTHON\veteye2\checkpoints\usg_pregnancy_model_inceptionv3_380x380_final.keras
[2025-05-13 11:08:01] SUKCES: Model wykrywania ciąży załadowany pomyślnie
[2025-05-13 11:08:01] BŁĄD: Nie znaleziono modelu szacowania dnia ciąży
D:\PYTHON\veteye2\logs\training_log_2025-05-13.txt
NoneType: None

[2025-05-13 11:09:53] BŁĄD: Błąd generowania raportu: "Style 'MyNormal ' not found in stylesheet"
D:\PYTHON\veteye2\logs\training_log_2025-05-13.txt
Traceback (most recent call last):
  File "D:\python\veteye2\veteye2_env\lib\site-packages\reportlab\lib\styles.py", line 230, in __getitem__
    return self.byAlias[key]
KeyError: 'MyNormal '

During handling of the above exception, another exception occurred:

Traceback (most recent call last):
  File "D:\python\veteye2\veteye2_env\lib\site-packages\reportlab\lib\styles.py", line 233, in __getitem__
    return self.byName[key]
KeyError: 'MyNormal '

During handling of the above exception, another exception occurred:

Traceback (most recent call last):
  File "D:\PYTHON\veteye2\scripts\analysis_gui.py", line 388, in generate_report
    report_path = generate_pdf_report(
  File "D:\PYTHON\veteye2\scripts\diagnostic_utils.py", line 257, in generate_pdf_report
    story.append(Paragraph(line, styles["MyNormal "]))
  File "D:\python\veteye2\veteye2_env\lib\site-packages\reportlab\lib\styles.py", line 235, in __getitem__
    raise KeyError("Style '%s' not found in stylesheet" % key)
KeyError: "Style 'MyNormal ' not found in stylesheet"

[2025-05-13 11:10:45] BŁĄD: Błąd generowania raportu: "Style 'MyNormal ' not found in stylesheet"
D:\PYTHON\veteye2\logs\training_log_2025-05-13.txt
Traceback (most recent call last):
  File "D:\python\veteye2\veteye2_env\lib\site-packages\reportlab\lib\styles.py", line 230, in __getitem__
    return self.byAlias[key]
KeyError: 'MyNormal '

During handling of the above exception, another exception occurred:

Traceback (most recent call last):
  File "D:\python\veteye2\veteye2_env\lib\site-packages\reportlab\lib\styles.py", line 233, in __getitem__
    return self.byName[key]
KeyError: 'MyNormal '

During handling of the above exception, another exception occurred:

Traceback (most recent call last):
  File "D:\PYTHON\veteye2\scripts\analysis_gui.py", line 388, in generate_report
    report_path = generate_pdf_report(
  File "D:\PYTHON\veteye2\scripts\diagnostic_utils.py", line 257, in generate_pdf_report
    story.append(Paragraph(line, styles["MyNormal"]))
  File "D:\python\veteye2\veteye2_env\lib\site-packages\reportlab\lib\styles.py", line 235, in __getitem__
    raise KeyError("Style '%s' not found in stylesheet" % key)
KeyError: "Style 'MyNormal ' not found in stylesheet"

[2025-05-13 11:11:03] BŁĄD: Błąd generowania raportu: "Style 'MyNormal ' not found in stylesheet"
D:\PYTHON\veteye2\logs\training_log_2025-05-13.txt
Traceback (most recent call last):
  File "D:\python\veteye2\veteye2_env\lib\site-packages\reportlab\lib\styles.py", line 230, in __getitem__
    return self.byAlias[key]
KeyError: 'MyNormal '

During handling of the above exception, another exception occurred:

Traceback (most recent call last):
  File "D:\python\veteye2\veteye2_env\lib\site-packages\reportlab\lib\styles.py", line 233, in __getitem__
    return self.byName[key]
KeyError: 'MyNormal '

During handling of the above exception, another exception occurred:

Traceback (most recent call last):
  File "D:\PYTHON\veteye2\scripts\analysis_gui.py", line 388, in generate_report
    report_path = generate_pdf_report(
  File "D:\PYTHON\veteye2\scripts\diagnostic_utils.py", line 257, in generate_pdf_report
    story.append(Paragraph(line, styles['MyNormal']))
  File "D:\python\veteye2\veteye2_env\lib\site-packages\reportlab\lib\styles.py", line 235, in __getitem__
    raise KeyError("Style '%s' not found in stylesheet" % key)
KeyError: "Style 'MyNormal ' not found in stylesheet"

[2025-05-13 11:11:16] INFO: Używanie najnowszego modelu: D:\PYTHON\veteye2\checkpoints\usg_pregnancy_model_inceptionv3_380x380_final.keras
[2025-05-13 11:11:16] INFO: Uruchomiono interfejs analizy obrazów USG
[2025-05-13 11:11:16] INFO: Ładowanie modelu wykrywania ciąży: D:\PYTHON\veteye2\checkpoints\usg_pregnancy_model_inceptionv3_380x380_final.keras
[2025-05-13 11:11:19] SUKCES: Model wykrywania ciąży załadowany pomyślnie
[2025-05-13 11:11:19] BŁĄD: Nie znaleziono modelu szacowania dnia ciąży
D:\PYTHON\veteye2\logs\training_log_2025-05-13.txt
NoneType: None

[2025-05-13 11:17:15] INFO: Używanie najnowszego modelu: D:\PYTHON\veteye2\checkpoints\usg_pregnancy_model_inceptionv3_380x380_final.keras
[2025-05-13 11:17:15] INFO: Uruchomiono interfejs analizy obrazów USG
[2025-05-13 11:17:15] INFO: Ładowanie modelu wykrywania ciąży: D:\PYTHON\veteye2\checkpoints\usg_pregnancy_model_inceptionv3_380x380_final.keras
[2025-05-13 11:17:17] SUKCES: Model wykrywania ciąży załadowany pomyślnie
[2025-05-13 11:17:17] BŁĄD: Nie znaleziono modelu szacowania dnia ciąży
D:\PYTHON\veteye2\logs\training_log_2025-05-13.txt
NoneType: None

[2025-05-13 11:31:09] INFO: Używanie najnowszego modelu: D:\PYTHON\veteye2\checkpoints\usg_pregnancy_model_inceptionv3_380x380_final.keras
[2025-05-13 11:31:09] INFO: Uruchomiono interfejs analizy obrazów USG
[2025-05-13 11:31:09] INFO: Ładowanie modelu wykrywania ciąży: D:\PYTHON\veteye2\checkpoints\usg_pregnancy_model_inceptionv3_380x380_final.keras
[2025-05-13 11:31:11] SUKCES: Model wykrywania ciąży załadowany pomyślnie
[2025-05-13 11:31:11] BŁĄD: Nie znaleziono modelu szacowania dnia ciąży
D:\PYTHON\veteye2\logs\training_log_2025-05-13.txt
NoneType: None

[2025-05-13 11:34:45] INFO: Używanie najnowszego modelu: D:\PYTHON\veteye2\checkpoints\usg_pregnancy_model_inceptionv3_380x380_final.keras
[2025-05-13 11:34:45] INFO: Uruchomiono interfejs analizy obrazów USG
[2025-05-13 11:34:45] INFO: Ładowanie modelu wykrywania ciąży: D:\PYTHON\veteye2\checkpoints\usg_pregnancy_model_inceptionv3_380x380_final.keras
[2025-05-13 11:34:47] SUKCES: Model wykrywania ciąży załadowany pomyślnie
[2025-05-13 11:34:47] BŁĄD: Nie znaleziono modelu szacowania dnia ciąży
D:\PYTHON\veteye2\logs\training_log_2025-05-13.txt
NoneType: None

[2025-05-13 11:39:27] INFO: Używanie najnowszego modelu: D:\PYTHON\veteye2\checkpoints\usg_pregnancy_model_inceptionv3_380x380_final.keras
[2025-05-13 11:39:27] INFO: Uruchomiono interfejs analizy obrazów USG
[2025-05-13 11:39:27] INFO: Ładowanie modelu wykrywania ciąży: D:\PYTHON\veteye2\checkpoints\usg_pregnancy_model_inceptionv3_380x380_final.keras
[2025-05-13 11:39:29] SUKCES: Model wykrywania ciąży załadowany pomyślnie
[2025-05-13 11:39:29] BŁĄD: Nie znaleziono modelu szacowania dnia ciąży
D:\PYTHON\veteye2\logs\training_log_2025-05-13.txt
NoneType: None

[2025-05-13 11:41:49] INFO: Używanie najnowszego modelu: D:\PYTHON\veteye2\checkpoints\usg_pregnancy_model_inceptionv3_380x380_final.keras
[2025-05-13 11:41:49] INFO: Uruchomiono interfejs analizy obrazów USG
[2025-05-13 11:41:49] INFO: Ładowanie modelu wykrywania ciąży: D:\PYTHON\veteye2\checkpoints\usg_pregnancy_model_inceptionv3_380x380_final.keras
[2025-05-13 11:41:51] SUKCES: Model wykrywania ciąży załadowany pomyślnie
[2025-05-13 11:41:51] BŁĄD: Nie znaleziono modelu szacowania dnia ciąży
D:\PYTHON\veteye2\logs\training_log_2025-05-13.txt
NoneType: None

[2025-05-13 11:45:13] INFO: Używanie najnowszego modelu: D:\PYTHON\veteye2\checkpoints\usg_pregnancy_model_inceptionv3_380x380_final.keras
[2025-05-13 11:45:13] INFO: Uruchomiono interfejs analizy obrazów USG
[2025-05-13 11:45:13] INFO: Ładowanie modelu wykrywania ciąży: D:\PYTHON\veteye2\checkpoints\usg_pregnancy_model_inceptionv3_380x380_final.keras
[2025-05-13 11:45:16] SUKCES: Model wykrywania ciąży załadowany pomyślnie
[2025-05-13 11:45:16] BŁĄD: Nie znaleziono modelu szacowania dnia ciąży
D:\PYTHON\veteye2\logs\training_log_2025-05-13.txt
NoneType: None

[2025-05-13 11:45:47] BŁĄD: Błąd generowania raportu: 
paragraph text '<para><u><b>\u2022 mean_intensity \u2013 \u015brednia jasno\u015b\u0107 pikseli obrazu.<u/><b/><br/>Typowy zakres dobrej jako\u015bci: 0.2 \u2013 0.5.<br/>Znaczenie diagnostyczne: Zbyt niska = niedo\u015bwietlony obraz; zbyt wysoka = prze\u015bwietlony.</para>' caused exception Parse error: saw </para> instead of expected </b>
D:\PYTHON\veteye2\logs\training_log_2025-05-13.txt
Traceback (most recent call last):
  File "D:\python\veteye2\veteye2_env\lib\site-packages\reportlab\platypus\paraparser.py", line 3218, in parse
    self.feed(text)
  File "D:\python\veteye2\veteye2_env\lib\html\parser.py", line 110, in feed
    self.goahead(0)
  File "D:\python\veteye2\veteye2_env\lib\html\parser.py", line 172, in goahead
    k = self.parse_endtag(i)
  File "D:\python\veteye2\veteye2_env\lib\html\parser.py", line 420, in parse_endtag
    self.handle_endtag(elem)
  File "D:\python\veteye2\veteye2_env\lib\site-packages\reportlab\platypus\paraparser.py", line 3254, in handle_endtag
    end()
  File "D:\python\veteye2\veteye2_env\lib\site-packages\reportlab\platypus\paraparser.py", line 2910, in end_para
    self._pop('para')
  File "D:\python\veteye2\veteye2_env\lib\site-packages\reportlab\platypus\paraparser.py", line 3066, in _pop
    raise ValueError('Parse error: saw </%s> instead of expected </%s>' % (tag,frag.__tag__))
ValueError: Parse error: saw </para> instead of expected </b>

During handling of the above exception, another exception occurred:

Traceback (most recent call last):
  File "D:\PYTHON\veteye2\scripts\analysis_gui.py", line 401, in generate_report
    report_path = generate_pdf_report(
  File "D:\PYTHON\veteye2\scripts\diagnostic_utils.py", line 260, in generate_pdf_report
    story.append(Paragraph(line, styles['MyNormal']))
  File "D:\python\veteye2\veteye2_env\lib\site-packages\reportlab\platypus\paragraph.py", line 1859, in __init__
    self._setup(text, style, bulletText or getattr(style,'bulletText',None), frags, cleanBlockQuotedText)
  File "D:\python\veteye2\veteye2_env\lib\site-packages\reportlab\platypus\paragraph.py", line 1880, in _setup
    style, frags, bulletTextFrags = _parser.parse(text,style)
  File "D:\python\veteye2\veteye2_env\lib\site-packages\reportlab\platypus\paraparser.py", line 3220, in parse
    annotateException('\nparagraph text %s caused exception' % ascii(text))
  File "D:\python\veteye2\veteye2_env\lib\site-packages\reportlab\lib\utils.py", line 1176, in annotateException
    rl_reraise(t,t(sep.join((_ for _ in (msg,str(v),postMsg) if _))),b)
  File "D:\python\veteye2\veteye2_env\lib\site-packages\reportlab\lib\utils.py", line 138, in rl_reraise
    raise v.with_traceback(b)
  File "D:\python\veteye2\veteye2_env\lib\site-packages\reportlab\platypus\paraparser.py", line 3218, in parse
    self.feed(text)
  File "D:\python\veteye2\veteye2_env\lib\html\parser.py", line 110, in feed
    self.goahead(0)
  File "D:\python\veteye2\veteye2_env\lib\html\parser.py", line 172, in goahead
    k = self.parse_endtag(i)
  File "D:\python\veteye2\veteye2_env\lib\html\parser.py", line 420, in parse_endtag
    self.handle_endtag(elem)
  File "D:\python\veteye2\veteye2_env\lib\site-packages\reportlab\platypus\paraparser.py", line 3254, in handle_endtag
    end()
  File "D:\python\veteye2\veteye2_env\lib\site-packages\reportlab\platypus\paraparser.py", line 2910, in end_para
    self._pop('para')
  File "D:\python\veteye2\veteye2_env\lib\site-packages\reportlab\platypus\paraparser.py", line 3066, in _pop
    raise ValueError('Parse error: saw </%s> instead of expected </%s>' % (tag,frag.__tag__))
ValueError: 
paragraph text '<para><u><b>\u2022 mean_intensity \u2013 \u015brednia jasno\u015b\u0107 pikseli obrazu.<u/><b/><br/>Typowy zakres dobrej jako\u015bci: 0.2 \u2013 0.5.<br/>Znaczenie diagnostyczne: Zbyt niska = niedo\u015bwietlony obraz; zbyt wysoka = prze\u015bwietlony.</para>' caused exception Parse error: saw </para> instead of expected </b>

[2025-05-13 11:47:53] INFO: Używanie najnowszego modelu: D:\PYTHON\veteye2\checkpoints\usg_pregnancy_model_inceptionv3_380x380_final.keras
[2025-05-13 11:47:53] INFO: Uruchomiono interfejs analizy obrazów USG
[2025-05-13 11:47:53] INFO: Ładowanie modelu wykrywania ciąży: D:\PYTHON\veteye2\checkpoints\usg_pregnancy_model_inceptionv3_380x380_final.keras
[2025-05-13 11:47:55] SUKCES: Model wykrywania ciąży załadowany pomyślnie
[2025-05-13 11:47:55] BŁĄD: Nie znaleziono modelu szacowania dnia ciąży
D:\PYTHON\veteye2\logs\training_log_2025-05-13.txt
NoneType: None

[2025-05-13 11:48:06] BŁĄD: Błąd generowania raportu: 
paragraph text '<para><u><b>\u2022 mean_intensity \u2013 \u015brednia jasno\u015b\u0107 pikseli obrazu.</u></b><br/>Typowy zakres dobrej jako\u015bci: 0.2 \u2013 0.5.<br/>Znaczenie diagnostyczne: Zbyt niska = niedo\u015bwietlony obraz; zbyt wysoka = prze\u015bwietlony.</para>' caused exception Parse error: saw </u> instead of expected </b>
D:\PYTHON\veteye2\logs\training_log_2025-05-13.txt
Traceback (most recent call last):
  File "D:\python\veteye2\veteye2_env\lib\site-packages\reportlab\platypus\paraparser.py", line 3218, in parse
    self.feed(text)
  File "D:\python\veteye2\veteye2_env\lib\html\parser.py", line 110, in feed
    self.goahead(0)
  File "D:\python\veteye2\veteye2_env\lib\html\parser.py", line 172, in goahead
    k = self.parse_endtag(i)
  File "D:\python\veteye2\veteye2_env\lib\html\parser.py", line 420, in parse_endtag
    self.handle_endtag(elem)
  File "D:\python\veteye2\veteye2_env\lib\site-packages\reportlab\platypus\paraparser.py", line 3254, in handle_endtag
    end()
  File "D:\python\veteye2\veteye2_env\lib\site-packages\reportlab\platypus\paraparser.py", line 2641, in end_u
    self._pop('u')
  File "D:\python\veteye2\veteye2_env\lib\site-packages\reportlab\platypus\paraparser.py", line 3066, in _pop
    raise ValueError('Parse error: saw </%s> instead of expected </%s>' % (tag,frag.__tag__))
ValueError: Parse error: saw </u> instead of expected </b>

During handling of the above exception, another exception occurred:

Traceback (most recent call last):
  File "D:\PYTHON\veteye2\scripts\analysis_gui.py", line 401, in generate_report
    report_path = generate_pdf_report(
  File "D:\PYTHON\veteye2\scripts\diagnostic_utils.py", line 260, in generate_pdf_report
    story.append(Paragraph(line, styles['MyNormal']))
  File "D:\python\veteye2\veteye2_env\lib\site-packages\reportlab\platypus\paragraph.py", line 1859, in __init__
    self._setup(text, style, bulletText or getattr(style,'bulletText',None), frags, cleanBlockQuotedText)
  File "D:\python\veteye2\veteye2_env\lib\site-packages\reportlab\platypus\paragraph.py", line 1880, in _setup
    style, frags, bulletTextFrags = _parser.parse(text,style)
  File "D:\python\veteye2\veteye2_env\lib\site-packages\reportlab\platypus\paraparser.py", line 3220, in parse
    annotateException('\nparagraph text %s caused exception' % ascii(text))
  File "D:\python\veteye2\veteye2_env\lib\site-packages\reportlab\lib\utils.py", line 1176, in annotateException
    rl_reraise(t,t(sep.join((_ for _ in (msg,str(v),postMsg) if _))),b)
  File "D:\python\veteye2\veteye2_env\lib\site-packages\reportlab\lib\utils.py", line 138, in rl_reraise
    raise v.with_traceback(b)
  File "D:\python\veteye2\veteye2_env\lib\site-packages\reportlab\platypus\paraparser.py", line 3218, in parse
    self.feed(text)
  File "D:\python\veteye2\veteye2_env\lib\html\parser.py", line 110, in feed
    self.goahead(0)
  File "D:\python\veteye2\veteye2_env\lib\html\parser.py", line 172, in goahead
    k = self.parse_endtag(i)
  File "D:\python\veteye2\veteye2_env\lib\html\parser.py", line 420, in parse_endtag
    self.handle_endtag(elem)
  File "D:\python\veteye2\veteye2_env\lib\site-packages\reportlab\platypus\paraparser.py", line 3254, in handle_endtag
    end()
  File "D:\python\veteye2\veteye2_env\lib\site-packages\reportlab\platypus\paraparser.py", line 2641, in end_u
    self._pop('u')
  File "D:\python\veteye2\veteye2_env\lib\site-packages\reportlab\platypus\paraparser.py", line 3066, in _pop
    raise ValueError('Parse error: saw </%s> instead of expected </%s>' % (tag,frag.__tag__))
ValueError: 
paragraph text '<para><u><b>\u2022 mean_intensity \u2013 \u015brednia jasno\u015b\u0107 pikseli obrazu.</u></b><br/>Typowy zakres dobrej jako\u015bci: 0.2 \u2013 0.5.<br/>Znaczenie diagnostyczne: Zbyt niska = niedo\u015bwietlony obraz; zbyt wysoka = prze\u015bwietlony.</para>' caused exception Parse error: saw </u> instead of expected </b>

[2025-05-13 11:50:58] INFO: Używanie najnowszego modelu: D:\PYTHON\veteye2\checkpoints\usg_pregnancy_model_inceptionv3_380x380_final.keras
[2025-05-13 11:50:58] INFO: Uruchomiono interfejs analizy obrazów USG
[2025-05-13 11:50:59] INFO: Ładowanie modelu wykrywania ciąży: D:\PYTHON\veteye2\checkpoints\usg_pregnancy_model_inceptionv3_380x380_final.keras
[2025-05-13 11:51:01] SUKCES: Model wykrywania ciąży załadowany pomyślnie
[2025-05-13 11:51:01] BŁĄD: Nie znaleziono modelu szacowania dnia ciąży
D:\PYTHON\veteye2\logs\training_log_2025-05-13.txt
NoneType: None

[2025-05-13 11:59:24] INFO: Używanie najnowszego modelu: D:\PYTHON\veteye2\checkpoints\usg_pregnancy_model_inceptionv3_380x380_final.keras
[2025-05-13 11:59:24] INFO: Uruchomiono interfejs analizy obrazów USG
[2025-05-13 12:08:37] INFO: Używanie najnowszego modelu: D:\PYTHON\veteye2\checkpoints\usg_pregnancy_model_inceptionv3_380x380_final.keras
[2025-05-13 12:08:37] INFO: Uruchomiono interfejs analizy obrazów USG
[2025-05-13 12:08:37] INFO: Ładowanie modelu wykrywania ciąży: D:\PYTHON\veteye2\checkpoints\usg_pregnancy_model_inceptionv3_380x380_final.keras
[2025-05-13 12:08:40] SUKCES: Model wykrywania ciąży załadowany pomyślnie
[2025-05-13 12:08:40] BŁĄD: Nie znaleziono modelu szacowania dnia ciąży
D:\PYTHON\veteye2\logs\training_log_2025-05-13.txt
NoneType: None

[2025-05-13 12:12:18] INFO: Używanie najnowszego modelu: D:\PYTHON\veteye2\checkpoints\usg_pregnancy_model_inceptionv3_380x380_final.keras
[2025-05-13 12:12:18] INFO: Uruchomiono interfejs analizy obrazów USG
[2025-05-13 12:12:18] INFO: Ładowanie modelu wykrywania ciąży: D:\PYTHON\veteye2\checkpoints\usg_pregnancy_model_inceptionv3_380x380_final.keras
[2025-05-13 12:12:21] SUKCES: Model wykrywania ciąży załadowany pomyślnie
[2025-05-13 12:12:21] BŁĄD: Nie znaleziono modelu szacowania dnia ciąży
D:\PYTHON\veteye2\logs\training_log_2025-05-13.txt
NoneType: None

[2025-05-13 12:12:52] INFO: Używanie najnowszego modelu: D:\PYTHON\veteye2\checkpoints\usg_pregnancy_model_inceptionv3_380x380_final.keras
[2025-05-13 12:12:52] INFO: Uruchomiono interfejs analizy obrazów USG
[2025-05-13 12:12:52] INFO: Ładowanie modelu wykrywania ciąży: D:\PYTHON\veteye2\checkpoints\usg_pregnancy_model_inceptionv3_380x380_final.keras
[2025-05-13 12:12:54] SUKCES: Model wykrywania ciąży załadowany pomyślnie
[2025-05-13 12:12:54] BŁĄD: Nie znaleziono modelu szacowania dnia ciąży
D:\PYTHON\veteye2\logs\training_log_2025-05-13.txt
NoneType: None

[2025-05-13 12:17:03] INFO: Używanie najnowszego modelu: D:\PYTHON\veteye2\checkpoints\usg_pregnancy_model_inceptionv3_380x380_final.keras
[2025-05-13 12:17:03] INFO: Uruchomiono interfejs analizy obrazów USG
[2025-05-13 12:17:03] INFO: Ładowanie modelu wykrywania ciąży: D:\PYTHON\veteye2\checkpoints\usg_pregnancy_model_inceptionv3_380x380_final.keras
[2025-05-13 12:17:06] SUKCES: Model wykrywania ciąży załadowany pomyślnie
[2025-05-13 12:17:06] BŁĄD: Nie znaleziono modelu szacowania dnia ciąży
D:\PYTHON\veteye2\logs\training_log_2025-05-13.txt
NoneType: None

[2025-05-13 12:17:20] BŁĄD: Błąd predykcji: 'AnalysisGUI' object has no attribute 'legend_button'
D:\PYTHON\veteye2\logs\training_log_2025-05-13.txt
Traceback (most recent call last):
  File "D:\PYTHON\veteye2\scripts\analysis_gui.py", line 431, in analyze_current_image
    self.legend_button.config(state=tk.NORMAL)
AttributeError: 'AnalysisGUI' object has no attribute 'legend_button'

[2025-05-13 12:19:31] INFO: Używanie najnowszego modelu: D:\PYTHON\veteye2\checkpoints\usg_pregnancy_model_inceptionv3_380x380_final.keras
[2025-05-13 12:19:31] INFO: Uruchomiono interfejs analizy obrazów USG
[2025-05-13 12:19:31] INFO: Ładowanie modelu wykrywania ciąży: D:\PYTHON\veteye2\checkpoints\usg_pregnancy_model_inceptionv3_380x380_final.keras
[2025-05-13 12:19:33] SUKCES: Model wykrywania ciąży załadowany pomyślnie
[2025-05-13 12:19:33] BŁĄD: Nie znaleziono modelu szacowania dnia ciąży
D:\PYTHON\veteye2\logs\training_log_2025-05-13.txt
NoneType: None

[2025-05-13 12:20:54] INFO: Używanie najnowszego modelu: D:\PYTHON\veteye2\checkpoints\usg_pregnancy_model_inceptionv3_380x380_final.keras
[2025-05-13 12:20:54] INFO: Uruchomiono interfejs analizy obrazów USG
[2025-05-13 12:20:54] INFO: Ładowanie modelu wykrywania ciąży: D:\PYTHON\veteye2\checkpoints\usg_pregnancy_model_inceptionv3_380x380_final.keras
[2025-05-13 12:20:57] SUKCES: Model wykrywania ciąży załadowany pomyślnie
[2025-05-13 12:20:57] BŁĄD: Nie znaleziono modelu szacowania dnia ciąży
D:\PYTHON\veteye2\logs\training_log_2025-05-13.txt
NoneType: None

[2025-05-13 12:29:10] INFO: Używanie najnowszego modelu: D:\PYTHON\veteye2\checkpoints\usg_pregnancy_model_inceptionv3_380x380_final.keras
[2025-05-13 12:29:10] INFO: Uruchomiono interfejs analizy obrazów USG
[2025-05-13 12:29:10] INFO: Ładowanie modelu wykrywania ciąży: D:\PYTHON\veteye2\checkpoints\usg_pregnancy_model_inceptionv3_380x380_final.keras
[2025-05-13 12:29:13] SUKCES: Model wykrywania ciąży załadowany pomyślnie
[2025-05-13 12:29:13] BŁĄD: Nie znaleziono modelu szacowania dnia ciąży
D:\PYTHON\veteye2\logs\training_log_2025-05-13.txt
NoneType: None

[2025-05-13 12:36:58] INFO: Ładowanie modelu wykrywania ciąży: D:\PYTHON\veteye2\checkpoints\usg_pregnancy_model_inceptionv3_380x380_fina.keras
[2025-05-13 12:37:04] SUKCES: Model wykrywania ciąży załadowany pomyślnie
[2025-05-13 12:37:06] INFO: Ładowanie modelu wykrywania ciąży: D:\PYTHON\veteye2\checkpoints\usg_pregnancy_model_inceptionv3_380x380_fina.keras
[2025-05-13 12:37:14] SUKCES: Model wykrywania ciąży załadowany pomyślnie
[2025-05-13 12:41:46] INFO: Ładowanie modelu wykrywania ciąży: D:\PYTHON\veteye2\checkpoints\usg_pregnancy_model_inceptionv3_380x380_fina.keras
[2025-05-13 12:41:52] SUKCES: Model wykrywania ciąży załadowany pomyślnie
[2025-05-13 12:42:00] INFO: Ładowanie modelu wykrywania ciąży: D:\PYTHON\veteye2\checkpoints\usg_pregnancy_model_inceptionv3_380x380_fina.keras
[2025-05-13 12:42:07] SUKCES: Model wykrywania ciąży załadowany pomyślnie
[2025-05-13 12:43:35] INFO: Ładowanie modelu wykrywania ciąży: D:\PYTHON\veteye2\checkpoints\usg_pregnancy_model_inceptionv3_380x380_fina.keras
[2025-05-13 12:43:41] SUKCES: Model wykrywania ciąży załadowany pomyślnie
[2025-05-13 12:50:27] INFO: Ładowanie modelu wykrywania ciąży: D:\PYTHON\veteye2\checkpoints\usg_pregnancy_model_inceptionv3_380x380_fina.keras
[2025-05-13 12:50:33] SUKCES: Model wykrywania ciąży załadowany pomyślnie
[2025-05-13 12:50:35] INFO: Ładowanie modelu wykrywania ciąży: D:\PYTHON\veteye2\checkpoints\usg_pregnancy_model_inceptionv3_380x380_fina.keras
[2025-05-13 12:50:42] SUKCES: Model wykrywania ciąży załadowany pomyślnie
[2025-05-13 12:53:28] INFO: Ładowanie modelu wykrywania ciąży: D:\PYTHON\veteye2\checkpoints\usg_pregnancy_model_inceptionv3_380x380_fina.keras
[2025-05-13 12:53:34] SUKCES: Model wykrywania ciąży załadowany pomyślnie
[2025-05-13 12:53:36] INFO: Ładowanie modelu wykrywania ciąży: D:\PYTHON\veteye2\checkpoints\usg_pregnancy_model_inceptionv3_380x380_fina.keras
[2025-05-13 12:53:44] SUKCES: Model wykrywania ciąży załadowany pomyślnie
[2025-05-13 12:58:15] INFO: Ładowanie modelu wykrywania ciąży: D:\PYTHON\veteye2\checkpoints\usg_pregnancy_model_inceptionv3_380x380_fina.keras
[2025-05-13 12:58:21] SUKCES: Model wykrywania ciąży załadowany pomyślnie
[2025-05-13 12:58:24] INFO: Ładowanie modelu wykrywania ciąży: D:\PYTHON\veteye2\checkpoints\usg_pregnancy_model_inceptionv3_380x380_fina.keras
[2025-05-13 12:58:31] SUKCES: Model wykrywania ciąży załadowany pomyślnie
[2025-05-13 13:00:03] INFO: Ładowanie modelu wykrywania ciąży: D:\PYTHON\veteye2\checkpoints\usg_pregnancy_model_inceptionv3_380x380_fina.keras
[2025-05-13 13:00:10] SUKCES: Model wykrywania ciąży załadowany pomyślnie
[2025-05-13 13:00:12] INFO: Ładowanie modelu wykrywania ciąży: D:\PYTHON\veteye2\checkpoints\usg_pregnancy_model_inceptionv3_380x380_fina.keras
[2025-05-13 13:00:19] SUKCES: Model wykrywania ciąży załadowany pomyślnie
[2025-05-13 13:08:58] INFO: Ładowanie modelu wykrywania ciąży: D:\PYTHON\veteye2\checkpoints\usg_pregnancy_model_inceptionv3_380x380_fina.keras
[2025-05-13 13:09:05] SUKCES: Model wykrywania ciąży załadowany pomyślnie
[2025-05-13 13:09:07] INFO: Ładowanie modelu wykrywania ciąży: D:\PYTHON\veteye2\checkpoints\usg_pregnancy_model_inceptionv3_380x380_fina.keras
[2025-05-13 13:09:14] SUKCES: Model wykrywania ciąży załadowany pomyślnie
[2025-05-13 20:37:01] INFO: Używanie najnowszego modelu: D:\PYTHON\veteye2\checkpoints\usg_pregnancy_model_inceptionv3_380x380_final.keras
[2025-05-13 20:37:02] INFO: Uruchomiono interfejs analizy obrazów USG
[2025-05-13 20:37:02] INFO: Ładowanie modelu wykrywania ciąży: D:\PYTHON\veteye2\checkpoints\usg_pregnancy_model_inceptionv3_380x380_final.keras
[2025-05-13 20:37:04] SUKCES: Model wykrywania ciąży załadowany pomyślnie
[2025-05-13 20:37:04] BŁĄD: Nie znaleziono modelu szacowania dnia ciąży
D:\PYTHON\veteye2\logs\training_log_2025-05-13.txt
NoneType: None

[2025-05-13 20:41:35] INFO: Używanie najnowszego modelu: D:\PYTHON\veteye2\checkpoints\usg_pregnancy_model_inceptionv3_380x380_final.keras
[2025-05-13 20:41:35] INFO: Uruchomiono interfejs analizy obrazów USG
[2025-05-13 20:41:35] INFO: Ładowanie modelu wykrywania ciąży: D:\PYTHON\veteye2\checkpoints\usg_pregnancy_model_inceptionv3_380x380_final.keras
[2025-05-13 20:41:38] SUKCES: Model wykrywania ciąży załadowany pomyślnie
[2025-05-13 20:41:38] BŁĄD: Nie znaleziono modelu szacowania dnia ciąży
D:\PYTHON\veteye2\logs\training_log_2025-05-13.txt
NoneType: None

[2025-05-13 20:45:39] INFO: Używanie najnowszego modelu: D:\PYTHON\veteye2\checkpoints\usg_pregnancy_model_inceptionv3_380x380_final.keras
[2025-05-13 20:45:39] INFO: Uruchomiono interfejs analizy obrazów USG
[2025-05-13 20:45:39] INFO: Ładowanie modelu wykrywania ciąży: D:\PYTHON\veteye2\checkpoints\usg_pregnancy_model_inceptionv3_380x380_final.keras
[2025-05-13 20:45:41] SUKCES: Model wykrywania ciąży załadowany pomyślnie
[2025-05-13 20:45:41] BŁĄD: Nie znaleziono modelu szacowania dnia ciąży
D:\PYTHON\veteye2\logs\training_log_2025-05-13.txt
NoneType: None

