[2025-05-12 19:59:23] 
========================================
Trening modelu wykrywania ciąży u klaczy
========================================
[2025-05-12 19:59:23] INFO: Katalog treningowy: USG-Mares-Pregnancy-Dataset
[2025-05-12 19:59:23] INFO: Katalog testowy: D:\PYTHON\veteye2\USG-Mares-Pregnancy-Dataset\Test
[2025-05-12 19:59:23] INFO: Rozmiar obrazu: (380, 380), Batch size: 16
[2025-05-12 19:59:23] INFO: Liczba epok: 60 (bazowy) + 40 (fine-tuning)
[2025-05-12 19:59:23] INFO: Stopa uczenia: 0.0001
[2025-05-12 19:59:23] 
=============================
Ładowanie danych treningowych
=============================
[2025-05-12 19:59:23] 
================
Ładowanie danych
================
[2025-05-12 19:59:23] INFO: Znaleziono 2 klasy: {'Test': 0, 'Training': 1}
[2025-05-12 19:59:23] INFO: Dane treningowe: 1118 obrazów
[2025-05-12 19:59:23] INFO: Dane testowe: 218 obrazów
[2025-05-12 19:59:23] INFO: Kroki na epokę: 69
[2025-05-12 19:59:23] INFO: Kroki walidacji: 13
[2025-05-12 19:59:23] 
================
Tworzenie modelu
================
[2025-05-12 19:59:23] 
=================================
Tworzenie modelu wykrywania ciąży
=================================
[2025-05-12 19:59:27] INFO: Model wykrywania ciąży utworzony
[2025-05-12 19:59:27] 
====================
Rozpoczęcie treningu
====================
[2025-05-12 19:59:27] INFO: Logi TensorBoard będą zapisywane w D:\PYTHON\veteye2\logs\20250512-195927
[2025-05-12 19:59:27] 
==========================================
Rozpoczęcie trening modelu bazowego modelu
==========================================
[2025-05-12 19:59:27] INFO: Rozpoczynanie trening modelu bazowego (próba 1/3)...
[2025-05-12 20:09:47] BŁĄD: Nie znaleziono modelu. Można kontynuować, ale analiza nie będzie dostępna.
D:\python\veteye2\logs\training_log_2025-05-12.txt
NoneType: None

[2025-05-12 20:09:47] INFO: Uruchomiono interfejs analizy obrazów USG
[2025-05-12 20:09:47] INFO: Ładowanie modelu wykrywania ciąży: D:\python\veteye2\checkpoints\usg_pregnancy_model_inceptionv3_380x380_base_last.keras
[2025-05-12 20:09:49] SUKCES: Model wykrywania ciąży załadowany pomyślnie
[2025-05-12 20:09:49] BŁĄD: Nie znaleziono modelu szacowania dnia ciąży
D:\python\veteye2\logs\training_log_2025-05-12.txt
NoneType: None

[2025-05-12 20:14:15] BŁĄD: Nie znaleziono modelu. Można kontynuować, ale analiza nie będzie dostępna.
D:\python\veteye2\logs\training_log_2025-05-12.txt
NoneType: None

[2025-05-12 20:14:15] INFO: Uruchomiono interfejs analizy obrazów USG
[2025-05-12 20:14:15] INFO: Ładowanie modelu wykrywania ciąży: D:\python\veteye2\checkpoints\usg_pregnancy_model_inceptionv3_380x380_base_last.keras
[2025-05-12 20:14:18] SUKCES: Model wykrywania ciąży załadowany pomyślnie
[2025-05-12 20:14:18] BŁĄD: Nie znaleziono modelu szacowania dnia ciąży
D:\python\veteye2\logs\training_log_2025-05-12.txt
NoneType: None

[2025-05-12 20:14:58] BŁĄD: Błąd podczas ładowania obrazu do analizy: Nie można załadować obrazu: D:/PYTHON/wagaALK/images/pyn_w_macicy_brak ciąży.jpg
[2025-05-12 20:14:58] BŁĄD: Błąd podczas analizy obrazu: Nie udało się załadować obrazu do analizy
[2025-05-12 20:18:09] BŁĄD: Nie znaleziono modelu. Można kontynuować, ale analiza nie będzie dostępna.
D:\python\veteye2\logs\training_log_2025-05-12.txt
NoneType: None

[2025-05-12 20:18:09] INFO: Uruchomiono interfejs analizy obrazów USG
[2025-05-12 20:18:09] INFO: Ładowanie modelu wykrywania ciąży: D:\python\veteye2\checkpoints\usg_pregnancy_model_inceptionv3_380x380_base_last.keras
[2025-05-12 20:18:11] SUKCES: Model wykrywania ciąży załadowany pomyślnie
[2025-05-12 20:18:11] BŁĄD: Nie znaleziono modelu szacowania dnia ciąży
D:\python\veteye2\logs\training_log_2025-05-12.txt
NoneType: None

[2025-05-12 20:20:35] BŁĄD: Nie znaleziono modelu. Można kontynuować, ale analiza nie będzie dostępna.
D:\python\veteye2\logs\training_log_2025-05-12.txt
NoneType: None

[2025-05-12 20:20:35] INFO: Uruchomiono interfejs analizy obrazów USG
[2025-05-12 20:20:35] INFO: Ładowanie modelu wykrywania ciąży: D:\python\veteye2\checkpoints\usg_pregnancy_model_inceptionv3_380x380_base_last.keras
[2025-05-12 20:20:37] SUKCES: Model wykrywania ciąży załadowany pomyślnie
[2025-05-12 20:20:37] BŁĄD: Nie znaleziono modelu szacowania dnia ciąży
D:\python\veteye2\logs\training_log_2025-05-12.txt
NoneType: None

[2025-05-12 20:36:02] SUKCES: Trening modelu bazowego zakończony pomyślnie
[2025-05-12 20:36:02] INFO: Ładowanie najlepszego modelu bazowego do fine-tuningu
[2025-05-12 20:36:07] 
=================================
Rozpoczynanie fine-tuningu modelu
=================================
[2025-05-12 20:36:07] INFO: Odmrożono 93 z 311 warstw modelu bazowego
[2025-05-12 20:36:07] INFO: Model przekompilowany do fine-tuningu z LR=1e-05
[2025-05-12 20:36:07] INFO: Logi TensorBoard będą zapisywane w D:\PYTHON\veteye2\logs\20250512-203607
[2025-05-12 20:36:07] 
=====================================
Rozpoczęcie fine-tuning modelu modelu
=====================================
[2025-05-12 20:36:07] INFO: Rozpoczynanie fine-tuning modelu (próba 1/3)...
[2025-05-12 20:46:13] INFO: Używanie najnowszego modelu: D:\python\veteye2\checkpoints\usg_pregnancy_model_inceptionv3_380x380_finetuned_last.keras
[2025-05-12 20:46:13] INFO: Uruchomiono interfejs analizy obrazów USG
[2025-05-12 20:46:13] INFO: Ładowanie modelu wykrywania ciąży: D:\python\veteye2\checkpoints\usg_pregnancy_model_inceptionv3_380x380_finetuned_last.keras
[2025-05-12 20:46:15] SUKCES: Model wykrywania ciąży załadowany pomyślnie
[2025-05-12 20:46:15] BŁĄD: Nie znaleziono modelu szacowania dnia ciąży
D:\python\veteye2\logs\training_log_2025-05-12.txt
NoneType: None

[2025-05-12 20:47:09] BŁĄD: Błąd podczas ładowania obrazu do analizy: Nie można załadować obrazu: D:/PYTHON/wagaALK/images/pyn_w_macicy_brak ciąży.jpg
[2025-05-12 20:47:09] BŁĄD: Błąd podczas analizy obrazu: Nie udało się załadować obrazu do analizy
[2025-05-12 20:47:13] BŁĄD: Błąd podczas ładowania obrazu do analizy: Nie można załadować obrazu: D:/PYTHON/wagaALK/images/pyn_w_macicy_brak ciąży.jpg
[2025-05-12 20:47:13] BŁĄD: Błąd podczas analizy obrazu: Nie udało się załadować obrazu do analizy
[2025-05-12 20:55:48] BŁĄD: Błąd podczas ekstrahowania cech obrazu: The maximum grayscale value in the image should be smaller than the number of levels.
[2025-05-12 20:55:48] BŁĄD: Błąd podczas wizualizacji analizy obrazu: 'NoneType' object is not subscriptable
[2025-05-12 20:55:51] INFO: Predykcja ciąży dla D:/PYTHON/veteye2/images/zarodek_D13_dni_jpg_800x600_crop_sharpen_q95.jpg: CIĄŻA (pewność: 0.75)
[2025-05-12 20:55:51] BŁĄD: Nie znaleziono modelu szacowania dnia ciąży
D:\python\veteye2\logs\training_log_2025-05-12.txt
NoneType: None

[2025-05-12 20:55:51] SUKCES: Analiza zakończona. Raport zapisany w D:\python\veteye2\wyniki\analysis_20250512_205548\analysis_report.json
[2025-05-12 20:55:51] BŁĄD: Błąd podczas analizy obrazu: 'NoneType' object has no attribute 'get'
[2025-05-12 20:56:39] BŁĄD: Błąd podczas ładowania obrazu do analizy: Nie można załadować obrazu: D:/PYTHON/veteye2/images/pyn_w_macicy_brak ciąży.jpg
[2025-05-12 20:56:39] BŁĄD: Błąd podczas analizy obrazu: Nie udało się załadować obrazu do analizy
[2025-05-12 20:56:44] BŁĄD: Błąd podczas ładowania obrazu do analizy: Nie można załadować obrazu: D:/PYTHON/veteye2/images/pyn_w_macicy_brak ciąży.jpg
[2025-05-12 20:56:44] BŁĄD: Błąd podczas analizy obrazu: Nie udało się załadować obrazu do analizy
[2025-05-12 20:57:03] BŁĄD: Błąd podczas ekstrahowania cech obrazu: The maximum grayscale value in the image should be smaller than the number of levels.
[2025-05-12 20:57:03] BŁĄD: Błąd podczas wizualizacji analizy obrazu: 'NoneType' object is not subscriptable
[2025-05-12 20:57:03] INFO: Predykcja ciąży dla D:/PYTHON/veteye2/images/zarodek_D15_dni_jpg_800x600_crop_sharpen_q95.jpg: CIĄŻA (pewność: 0.70)
[2025-05-12 20:57:03] BŁĄD: Nie znaleziono modelu szacowania dnia ciąży
D:\python\veteye2\logs\training_log_2025-05-12.txt
NoneType: None

[2025-05-12 20:57:03] SUKCES: Analiza zakończona. Raport zapisany w D:\python\veteye2\wyniki\analysis_20250512_205703\analysis_report.json
[2025-05-12 20:57:03] BŁĄD: Błąd podczas analizy obrazu: 'NoneType' object has no attribute 'get'
[2025-05-12 20:58:34] INFO: Używanie najnowszego modelu: D:\python\veteye2\checkpoints\usg_pregnancy_model_inceptionv3_380x380_finetuned_last.keras
[2025-05-12 20:58:34] INFO: Uruchomiono interfejs analizy obrazów USG
[2025-05-12 20:58:34] INFO: Ładowanie modelu wykrywania ciąży: D:\python\veteye2\checkpoints\usg_pregnancy_model_inceptionv3_380x380_finetuned_last.keras
[2025-05-12 20:58:37] SUKCES: Model wykrywania ciąży załadowany pomyślnie
[2025-05-12 20:58:37] BŁĄD: Nie znaleziono modelu szacowania dnia ciąży
D:\python\veteye2\logs\training_log_2025-05-12.txt
NoneType: None

[2025-05-12 21:37:31] INFO: Używanie najnowszego modelu: D:\python\veteye2\checkpoints\usg_pregnancy_model_inceptionv3_380x380_finetuned_last.keras
[2025-05-12 21:37:31] INFO: Uruchomiono interfejs GUI
[2025-05-12 21:37:31] INFO: Ładowanie modelu wykrywania ciąży: D:\python\veteye2\checkpoints\usg_pregnancy_model_inceptionv3_380x380_finetuned_last.keras
[2025-05-12 21:37:34] SUKCES: Model wykrywania ciąży załadowany pomyślnie
[2025-05-12 21:38:03] BŁĄD: Błąd analizy: name 'tf' is not defined
D:\python\veteye2\logs\training_log_2025-05-12.txt
Traceback (most recent call last):
  File "D:\python\veteye2\scripts\analysis_gui.py", line 147, in analyze_current_image
    predicted_class, confidence, description = predict_image(
  File "D:\python\veteye2\scripts\prediction.py", line 306, in predict_image
    img = tf.keras.preprocessing.image.load_img(image_path, target_size=image_size)
NameError: name 'tf' is not defined

[2025-05-12 21:38:38] BŁĄD: Błąd analizy: name 'tf' is not defined
D:\python\veteye2\logs\training_log_2025-05-12.txt
Traceback (most recent call last):
  File "D:\python\veteye2\scripts\analysis_gui.py", line 147, in analyze_current_image
    predicted_class, confidence, description = predict_image(
  File "D:\python\veteye2\scripts\prediction.py", line 306, in predict_image
    img = tf.keras.preprocessing.image.load_img(image_path, target_size=image_size)
NameError: name 'tf' is not defined

[2025-05-12 21:39:59] BŁĄD: Błąd analizy: name 'tf' is not defined
D:\python\veteye2\logs\training_log_2025-05-12.txt
Traceback (most recent call last):
  File "D:\python\veteye2\scripts\analysis_gui.py", line 147, in analyze_current_image
    predicted_class, confidence, description = predict_image(
  File "D:\python\veteye2\scripts\prediction.py", line 306, in predict_image
    from diagnostic_utils import analyze_image_features, generate_description
NameError: name 'tf' is not defined

[2025-05-12 21:40:15] INFO: Używanie najnowszego modelu: D:\python\veteye2\checkpoints\usg_pregnancy_model_inceptionv3_380x380_finetuned_last.keras
[2025-05-12 21:40:15] INFO: Uruchomiono interfejs GUI
[2025-05-12 21:40:15] INFO: Ładowanie modelu wykrywania ciąży: D:\python\veteye2\checkpoints\usg_pregnancy_model_inceptionv3_380x380_finetuned_last.keras
[2025-05-12 21:40:18] SUKCES: Model wykrywania ciąży załadowany pomyślnie
[2025-05-12 21:40:28] SUKCES: Fine-tuning modelu zakończony pomyślnie
[2025-05-12 21:40:28] 
================
Ewaluacja modelu
================
[2025-05-12 21:40:28] 
=================================
Ewaluacja modelu wykrywania ciąży
=================================
[2025-05-12 21:40:28] INFO: Wykonywanie predykcji na zbiorze testowym...
[2025-05-12 21:40:33] INFO: 
Raport klasyfikacji:
[2025-05-12 21:40:33] INFO: 
              precision    recall  f1-score   support

        Test       0.73      0.18      0.29       105
    Training       0.55      0.94      0.70       113

    accuracy                           0.57       218
   macro avg       0.64      0.56      0.49       218
weighted avg       0.64      0.57      0.50       218

[2025-05-12 21:40:33] BŁĄD: Błąd podczas ewaluacji modelu wykrywania ciąży
name 'plt' is not defined
Traceback (most recent call last):
  File "D:\PYTHON\veteye2\scripts\evaluation.py", line 58, in evaluate_pregnancy_model
    plt.figure(figsize=(10, 8))
NameError: name 'plt' is not defined

[2025-05-12 21:40:33] BŁĄD: Ewaluacja modelu nie powiodła się
[2025-05-12 21:40:34] BŁĄD: Błąd analizy: [Errno 2] No such file or directory: 'wyniki\\usg_report_zarodek_D13_dni_jpg_800x600_crop_sharpen_q95.pdf'
D:\python\veteye2\logs\training_log_2025-05-12.txt
Traceback (most recent call last):
  File "D:\python\veteye2\scripts\analysis_gui.py", line 155, in analyze_current_image
    report_path = generate_pdf_report(
  File "D:\python\veteye2\scripts\diagnostic_utils.py", line 93, in generate_pdf_report
    doc.build(story)
  File "D:\python\veteye2\veteye2_env\lib\site-packages\reportlab\platypus\doctemplate.py", line 1322, in build
    BaseDocTemplate.build(self,flowables, canvasmaker=canvasmaker)
  File "D:\python\veteye2\veteye2_env\lib\site-packages\reportlab\platypus\doctemplate.py", line 1109, in build
    self._endBuild()
  File "D:\python\veteye2\veteye2_env\lib\site-packages\reportlab\platypus\doctemplate.py", line 1044, in _endBuild
    if getattr(self,'_doSave',1): self.canv.save()
  File "D:\python\veteye2\veteye2_env\lib\site-packages\reportlab\pdfgen\canvas.py", line 1301, in save
    self._doc.SaveToFile(self._filename, self)
  File "D:\python\veteye2\veteye2_env\lib\site-packages\reportlab\pdfbase\pdfdoc.py", line 208, in SaveToFile
    f = open(filename, "wb")
FileNotFoundError: [Errno 2] No such file or directory: 'wyniki\\usg_report_zarodek_D13_dni_jpg_800x600_crop_sharpen_q95.pdf'

[2025-05-12 21:42:16] BŁĄD: Błąd analizy: [Errno 2] No such file or directory: 'wyniki\\usg_report_zarodek_D13_dni_jpg_800x600_crop_sharpen_q95.pdf'
D:\python\veteye2\logs\training_log_2025-05-12.txt
Traceback (most recent call last):
  File "D:\python\veteye2\scripts\analysis_gui.py", line 155, in analyze_current_image
    report_path = generate_pdf_report(
  File "D:\python\veteye2\scripts\diagnostic_utils.py", line 93, in generate_pdf_report
    story.append(Paragraph(paragraph, styles['MyNormal']))
  File "D:\python\veteye2\veteye2_env\lib\site-packages\reportlab\platypus\doctemplate.py", line 1322, in build
    BaseDocTemplate.build(self,flowables, canvasmaker=canvasmaker)
  File "D:\python\veteye2\veteye2_env\lib\site-packages\reportlab\platypus\doctemplate.py", line 1109, in build
    self._endBuild()
  File "D:\python\veteye2\veteye2_env\lib\site-packages\reportlab\platypus\doctemplate.py", line 1044, in _endBuild
    if getattr(self,'_doSave',1): self.canv.save()
  File "D:\python\veteye2\veteye2_env\lib\site-packages\reportlab\pdfgen\canvas.py", line 1301, in save
    self._doc.SaveToFile(self._filename, self)
  File "D:\python\veteye2\veteye2_env\lib\site-packages\reportlab\pdfbase\pdfdoc.py", line 208, in SaveToFile
    f = open(filename, "wb")
FileNotFoundError: [Errno 2] No such file or directory: 'wyniki\\usg_report_zarodek_D13_dni_jpg_800x600_crop_sharpen_q95.pdf'

[2025-05-12 21:42:52] INFO: Używanie najnowszego modelu: D:\python\veteye2\checkpoints\usg_pregnancy_model_inceptionv3_380x380_finetuned_last.keras
[2025-05-12 21:42:52] INFO: Uruchomiono interfejs GUI
[2025-05-12 21:42:52] INFO: Ładowanie modelu wykrywania ciąży: D:\python\veteye2\checkpoints\usg_pregnancy_model_inceptionv3_380x380_finetuned_last.keras
[2025-05-12 21:42:54] SUKCES: Model wykrywania ciąży załadowany pomyślnie
[2025-05-12 21:45:22] 
========================================
Trening modelu wykrywania ciąży u klaczy
========================================
[2025-05-12 21:45:22] INFO: Katalog treningowy: D:\python\veteye2/USG-Mares-Pregnancy-Dataset
[2025-05-12 21:45:22] INFO: Katalog testowy: D:\python\veteye2\USG-Mares-Pregnancy-Dataset\Test
[2025-05-12 21:45:22] INFO: Rozmiar obrazu: (380, 380), Batch size: 16
[2025-05-12 21:45:22] INFO: Liczba epok: 60 (bazowy) + 40 (fine-tuning)
[2025-05-12 21:45:22] INFO: Stopa uczenia: 0.0001
[2025-05-12 21:45:22] 
=============================
Ładowanie danych treningowych
=============================
[2025-05-12 21:45:22] 
================
Ładowanie danych
================
[2025-05-12 21:45:22] INFO: Znaleziono 2 klasy: {'Test': 0, 'Training': 1}
[2025-05-12 21:45:22] INFO: Dane treningowe: 1118 obrazów
[2025-05-12 21:45:22] INFO: Dane testowe: 218 obrazów
[2025-05-12 21:45:22] INFO: Kroki na epokę: 69
[2025-05-12 21:45:22] INFO: Kroki walidacji: 13
[2025-05-12 21:45:22] INFO: Wznowienie treningu z istniejącego punktu kontrolnego: D:\python\veteye2\checkpoints\usg_pregnancy_model_inceptionv3_380x380_base.keras
[2025-05-12 21:45:24] 
====================
Rozpoczęcie treningu
====================
[2025-05-12 21:45:24] INFO: Logi TensorBoard będą zapisywane w D:\python\veteye2\logs\20250512-214524
[2025-05-12 21:45:24] 
==========================================
Rozpoczęcie trening modelu bazowego modelu
==========================================
[2025-05-12 21:45:24] INFO: Rozpoczynanie trening modelu bazowego (próba 1/3)...
[2025-05-12 21:46:19] 
========================================
Trening modelu wykrywania ciąży u klaczy
========================================
[2025-05-12 21:46:19] INFO: Katalog treningowy: D:\python\veteye2/USG-Mares-Pregnancy-Dataset
[2025-05-12 21:46:19] INFO: Katalog testowy: D:\python\veteye2\USG-Mares-Pregnancy-Dataset\Test
[2025-05-12 21:46:19] INFO: Rozmiar obrazu: (380, 380), Batch size: 16
[2025-05-12 21:46:19] INFO: Liczba epok: 60 (bazowy) + 40 (fine-tuning)
[2025-05-12 21:46:19] INFO: Stopa uczenia: 0.0001
[2025-05-12 21:46:19] 
=============================
Ładowanie danych treningowych
=============================
[2025-05-12 21:46:19] 
================
Ładowanie danych
================
[2025-05-12 21:46:19] INFO: Znaleziono 2 klasy: {'Test': 0, 'Training': 1}
[2025-05-12 21:46:19] INFO: Dane treningowe: 1118 obrazów
[2025-05-12 21:46:19] INFO: Dane testowe: 218 obrazów
[2025-05-12 21:46:19] INFO: Kroki na epokę: 69
[2025-05-12 21:46:19] INFO: Kroki walidacji: 13
[2025-05-12 21:46:19] 
================
Tworzenie modelu
================
[2025-05-12 21:46:19] 
=================================
Tworzenie modelu wykrywania ciąży
=================================
[2025-05-12 21:46:21] INFO: Model wykrywania ciąży utworzony
[2025-05-12 21:46:21] 
====================
Rozpoczęcie treningu
====================
[2025-05-12 21:46:21] INFO: Logi TensorBoard będą zapisywane w D:\python\veteye2\logs\20250512-214621
[2025-05-12 21:46:21] 
==========================================
Rozpoczęcie trening modelu bazowego modelu
==========================================
[2025-05-12 21:46:21] INFO: Rozpoczynanie trening modelu bazowego (próba 1/3)...
[2025-05-12 21:47:27] BŁĄD: Nie znaleziono modelu. Można kontynuować, ale analiza nie będzie dostępna.
D:\PYTHON\veteye2\logs\training_log_2025-05-12.txt
NoneType: None

[2025-05-12 21:47:27] INFO: Uruchomiono interfejs GUI
[2025-05-12 21:47:27] INFO: Ładowanie modelu wykrywania ciąży: D:\PYTHON\veteye2\checkpoints\usg_pregnancy_model_inceptionv3_380x380_base_last.keras
[2025-05-12 21:47:30] SUKCES: Model wykrywania ciąży załadowany pomyślnie
[2025-05-12 21:47:39] BŁĄD: Błąd analizy: [Errno 13] Permission denied: 'wyniki\\usg_report_zarodek_D13_dni_jpg_800x600_crop_sharpen_q95.pdf'
D:\PYTHON\veteye2\logs\training_log_2025-05-12.txt
Traceback (most recent call last):
  File "D:\PYTHON\veteye2\scripts\analysis_gui.py", line 155, in analyze_current_image
    report_path = generate_pdf_report(
  File "D:\PYTHON\veteye2\scripts\diagnostic_utils.py", line 94, in generate_pdf_report
    doc.build(story)
  File "D:\python\veteye2\veteye2_env\lib\site-packages\reportlab\platypus\doctemplate.py", line 1322, in build
    BaseDocTemplate.build(self,flowables, canvasmaker=canvasmaker)
  File "D:\python\veteye2\veteye2_env\lib\site-packages\reportlab\platypus\doctemplate.py", line 1109, in build
    self._endBuild()
  File "D:\python\veteye2\veteye2_env\lib\site-packages\reportlab\platypus\doctemplate.py", line 1044, in _endBuild
    if getattr(self,'_doSave',1): self.canv.save()
  File "D:\python\veteye2\veteye2_env\lib\site-packages\reportlab\pdfgen\canvas.py", line 1301, in save
    self._doc.SaveToFile(self._filename, self)
  File "D:\python\veteye2\veteye2_env\lib\site-packages\reportlab\pdfbase\pdfdoc.py", line 208, in SaveToFile
    f = open(filename, "wb")
PermissionError: [Errno 13] Permission denied: 'wyniki\\usg_report_zarodek_D13_dni_jpg_800x600_crop_sharpen_q95.pdf'

[2025-05-12 21:53:07] SUKCES: Trening modelu bazowego zakończony pomyślnie
[2025-05-12 21:53:07] INFO: Ładowanie najlepszego modelu bazowego do fine-tuningu
[2025-05-12 21:53:09] 
=================================
Rozpoczynanie fine-tuningu modelu
=================================
[2025-05-12 21:53:09] INFO: Odmrożono 93 z 311 warstw modelu bazowego
[2025-05-12 21:53:09] INFO: Model przekompilowany do fine-tuningu z LR=1e-05
[2025-05-12 21:53:09] INFO: Logi TensorBoard będą zapisywane w D:\python\veteye2\logs\20250512-215309
[2025-05-12 21:53:09] 
=====================================
Rozpoczęcie fine-tuning modelu modelu
=====================================
[2025-05-12 21:53:09] INFO: Rozpoczynanie fine-tuning modelu (próba 1/3)...
[2025-05-12 21:55:10] INFO: Używanie najnowszego modelu: D:\python\veteye2\checkpoints\usg_pregnancy_model_inceptionv3_380x380_final.keras
[2025-05-12 21:55:10] INFO: Uruchomiono interfejs GUI
[2025-05-12 21:55:10] INFO: Ładowanie modelu wykrywania ciąży: D:\python\veteye2\checkpoints\usg_pregnancy_model_inceptionv3_380x380_final.keras
[2025-05-12 21:55:12] SUKCES: Model wykrywania ciąży załadowany pomyślnie
[2025-05-12 22:40:58] INFO: Używanie najnowszego modelu: D:\python\veteye2\checkpoints\usg_pregnancy_model_inceptionv3_380x380_final.keras
[2025-05-12 22:40:59] INFO: Uruchomiono interfejs analizy obrazów USG
[2025-05-12 22:40:59] INFO: Ładowanie modelu wykrywania ciąży: D:\python\veteye2\checkpoints\usg_pregnancy_model_inceptionv3_380x380_final.keras
[2025-05-12 22:41:01] SUKCES: Model wykrywania ciąży załadowany pomyślnie
[2025-05-12 22:41:01] BŁĄD: Nie znaleziono modelu szacowania dnia ciąży
D:\python\veteye2\logs\training_log_2025-05-12.txt
NoneType: None

[2025-05-12 22:41:12] BŁĄD: Błąd predykcji: name 'tf' is not defined
D:\python\veteye2\logs\training_log_2025-05-12.txt
Traceback (most recent call last):
  File "D:\python\veteye2\scripts\analysis_gui.py", line 120, in analyze_current_image
    img = tf.keras.preprocessing.image.load_img(self.current_image_path, target_size=IMAGE_SIZE)
NameError: name 'tf' is not defined

[2025-05-12 22:42:37] INFO: Używanie najnowszego modelu: D:\python\veteye2\checkpoints\usg_pregnancy_model_inceptionv3_380x380_final.keras
[2025-05-12 22:42:37] INFO: Uruchomiono interfejs analizy obrazów USG
[2025-05-12 22:42:37] INFO: Ładowanie modelu wykrywania ciąży: D:\python\veteye2\checkpoints\usg_pregnancy_model_inceptionv3_380x380_final.keras
[2025-05-12 22:42:39] SUKCES: Model wykrywania ciąży załadowany pomyślnie
[2025-05-12 22:42:39] BŁĄD: Nie znaleziono modelu szacowania dnia ciąży
D:\python\veteye2\logs\training_log_2025-05-12.txt
NoneType: None

[2025-05-12 22:42:45] BŁĄD: Błąd predykcji: local variable 'desc' referenced before assignment
D:\python\veteye2\logs\training_log_2025-05-12.txt
Traceback (most recent call last):
  File "D:\python\veteye2\scripts\analysis_gui.py", line 128, in analyze_current_image
    description = generate_description(predicted_class, confidence, image_path=self.current_image_path, additional_info=additional_info)
  File "D:\python\veteye2\scripts\diagnostic_utils.py", line 162, in generate_description
    desc += f"\n\nOpis wygenerowany automatycznie. Wymagana weryfikacja lekarza weterynarii."
UnboundLocalError: local variable 'desc' referenced before assignment

[2025-05-12 22:44:26] INFO: Używanie najnowszego modelu: D:\python\veteye2\checkpoints\usg_pregnancy_model_inceptionv3_380x380_final.keras
[2025-05-12 22:44:26] INFO: Uruchomiono interfejs analizy obrazów USG
[2025-05-12 22:44:26] INFO: Ładowanie modelu wykrywania ciąży: D:\python\veteye2\checkpoints\usg_pregnancy_model_inceptionv3_380x380_final.keras
[2025-05-12 22:44:29] SUKCES: Model wykrywania ciąży załadowany pomyślnie
[2025-05-12 22:44:29] BŁĄD: Nie znaleziono modelu szacowania dnia ciąży
D:\python\veteye2\logs\training_log_2025-05-12.txt
NoneType: None

[2025-05-12 22:44:35] BŁĄD: Błąd predykcji: local variable 'desc' referenced before assignment
D:\python\veteye2\logs\training_log_2025-05-12.txt
Traceback (most recent call last):
  File "D:\python\veteye2\scripts\analysis_gui.py", line 128, in analyze_current_image
    description = generate_description(predicted_class, confidence, image_path=self.current_image_path, additional_info=additional_info)
  File "D:\python\veteye2\scripts\diagnostic_utils.py", line 163, in generate_description
    return desc
UnboundLocalError: local variable 'desc' referenced before assignment

[2025-05-12 22:44:59] INFO: Używanie najnowszego modelu: D:\python\veteye2\checkpoints\usg_pregnancy_model_inceptionv3_380x380_final.keras
[2025-05-12 22:44:59] INFO: Uruchomiono interfejs analizy obrazów USG
[2025-05-12 22:44:59] INFO: Ładowanie modelu wykrywania ciąży: D:\python\veteye2\checkpoints\usg_pregnancy_model_inceptionv3_380x380_final.keras
[2025-05-12 22:45:01] SUKCES: Model wykrywania ciąży załadowany pomyślnie
[2025-05-12 22:45:01] BŁĄD: Nie znaleziono modelu szacowania dnia ciąży
D:\python\veteye2\logs\training_log_2025-05-12.txt
NoneType: None

[2025-05-12 22:45:06] BŁĄD: Błąd predykcji: local variable 'desc' referenced before assignment
D:\python\veteye2\logs\training_log_2025-05-12.txt
Traceback (most recent call last):
  File "D:\python\veteye2\scripts\analysis_gui.py", line 128, in analyze_current_image
    description = generate_description(predicted_class, confidence, image_path=self.current_image_path, additional_info=additional_info)
  File "D:\python\veteye2\scripts\diagnostic_utils.py", line 163, in generate_description
    return desc
UnboundLocalError: local variable 'desc' referenced before assignment

[2025-05-12 22:46:11] INFO: Używanie najnowszego modelu: D:\python\veteye2\checkpoints\usg_pregnancy_model_inceptionv3_380x380_final.keras
[2025-05-12 22:46:11] INFO: Uruchomiono interfejs analizy obrazów USG
[2025-05-12 22:46:11] INFO: Ładowanie modelu wykrywania ciąży: D:\python\veteye2\checkpoints\usg_pregnancy_model_inceptionv3_380x380_final.keras
[2025-05-12 22:46:13] SUKCES: Model wykrywania ciąży załadowany pomyślnie
[2025-05-12 22:46:13] BŁĄD: Nie znaleziono modelu szacowania dnia ciąży
D:\python\veteye2\logs\training_log_2025-05-12.txt
NoneType: None

[2025-05-12 22:46:50] BŁĄD: Błąd predykcji: local variable 'desc' referenced before assignment
D:\python\veteye2\logs\training_log_2025-05-12.txt
Traceback (most recent call last):
  File "D:\python\veteye2\scripts\analysis_gui.py", line 128, in analyze_current_image
    description = generate_description(predicted_class, confidence, image_path=self.current_image_path, additional_info=additional_info)
  File "D:\python\veteye2\scripts\diagnostic_utils.py", line 160, in generate_description
    desc = f"INFORMACJE O KLACZY:\n{mare_info}\n" + desc
UnboundLocalError: local variable 'desc' referenced before assignment

[2025-05-12 22:48:45] BŁĄD: Błąd predykcji: local variable 'desc' referenced before assignment
D:\python\veteye2\logs\training_log_2025-05-12.txt
Traceback (most recent call last):
  File "D:\python\veteye2\scripts\analysis_gui.py", line 128, in analyze_current_image
    description = generate_description(predicted_class, confidence, image_path=self.current_image_path, additional_info=additional_info)
  File "D:\python\veteye2\scripts\diagnostic_utils.py", line 160, in generate_description
    description = f"INFORMACJE O KLACZY:\n{mare_info}\n" + description
UnboundLocalError: local variable 'desc' referenced before assignment

[2025-05-12 22:48:48] BŁĄD: Błąd predykcji: local variable 'desc' referenced before assignment
D:\python\veteye2\logs\training_log_2025-05-12.txt
Traceback (most recent call last):
  File "D:\python\veteye2\scripts\analysis_gui.py", line 128, in analyze_current_image
    description = generate_description(predicted_class, confidence, image_path=self.current_image_path, additional_info=additional_info)
  File "D:\python\veteye2\scripts\diagnostic_utils.py", line 160, in generate_description
    description = f"INFORMACJE O KLACZY:\n{mare_info}\n" + description
UnboundLocalError: local variable 'desc' referenced before assignment

[2025-05-12 22:48:54] BŁĄD: Błąd predykcji: local variable 'desc' referenced before assignment
D:\python\veteye2\logs\training_log_2025-05-12.txt
Traceback (most recent call last):
  File "D:\python\veteye2\scripts\analysis_gui.py", line 128, in analyze_current_image
    description = generate_description(predicted_class, confidence, image_path=self.current_image_path, additional_info=additional_info)
  File "D:\python\veteye2\scripts\diagnostic_utils.py", line 160, in generate_description
    description = f"INFORMACJE O KLACZY:\n{mare_info}\n" + description
UnboundLocalError: local variable 'desc' referenced before assignment

[2025-05-12 22:49:15] INFO: Używanie najnowszego modelu: D:\python\veteye2\checkpoints\usg_pregnancy_model_inceptionv3_380x380_final.keras
[2025-05-12 22:49:15] INFO: Uruchomiono interfejs analizy obrazów USG
[2025-05-12 22:49:15] INFO: Ładowanie modelu wykrywania ciąży: D:\python\veteye2\checkpoints\usg_pregnancy_model_inceptionv3_380x380_final.keras
[2025-05-12 22:49:18] SUKCES: Model wykrywania ciąży załadowany pomyślnie
[2025-05-12 22:49:18] BŁĄD: Nie znaleziono modelu szacowania dnia ciąży
D:\python\veteye2\logs\training_log_2025-05-12.txt
NoneType: None

[2025-05-12 22:57:52] INFO: Używanie najnowszego modelu: D:\python\veteye2\checkpoints\usg_pregnancy_model_inceptionv3_380x380_final.keras
[2025-05-12 22:57:52] INFO: Uruchomiono interfejs analizy obrazów USG
[2025-05-12 22:57:52] INFO: Ładowanie modelu wykrywania ciąży: D:\python\veteye2\checkpoints\usg_pregnancy_model_inceptionv3_380x380_final.keras
[2025-05-12 22:57:54] SUKCES: Model wykrywania ciąży załadowany pomyślnie
[2025-05-12 22:57:54] BŁĄD: Nie znaleziono modelu szacowania dnia ciąży
D:\python\veteye2\logs\training_log_2025-05-12.txt
NoneType: None

[2025-05-12 23:10:42] INFO: Używanie najnowszego modelu: D:\python\veteye2\checkpoints\usg_pregnancy_model_inceptionv3_380x380_final.keras
[2025-05-12 23:10:42] INFO: Uruchomiono interfejs analizy obrazów USG
[2025-05-12 23:10:42] INFO: Ładowanie modelu wykrywania ciąży: D:\python\veteye2\checkpoints\usg_pregnancy_model_inceptionv3_380x380_final.keras
[2025-05-12 23:10:45] SUKCES: Model wykrywania ciąży załadowany pomyślnie
[2025-05-12 23:10:45] BŁĄD: Nie znaleziono modelu szacowania dnia ciąży
D:\python\veteye2\logs\training_log_2025-05-12.txt
NoneType: None

[2025-05-12 23:14:11] INFO: Używanie najnowszego modelu: D:\python\veteye2\checkpoints\usg_pregnancy_model_inceptionv3_380x380_final.keras
[2025-05-12 23:14:11] INFO: Uruchomiono interfejs analizy obrazów USG
[2025-05-12 23:17:26] INFO: Używanie najnowszego modelu: D:\python\veteye2\checkpoints\usg_pregnancy_model_inceptionv3_380x380_final.keras
[2025-05-12 23:17:26] INFO: Uruchomiono interfejs analizy obrazów USG
[2025-05-12 23:17:26] INFO: Ładowanie modelu wykrywania ciąży: D:\python\veteye2\checkpoints\usg_pregnancy_model_inceptionv3_380x380_final.keras
[2025-05-12 23:17:29] SUKCES: Model wykrywania ciąży załadowany pomyślnie
[2025-05-12 23:17:29] BŁĄD: Nie znaleziono modelu szacowania dnia ciąży
D:\python\veteye2\logs\training_log_2025-05-12.txt
NoneType: None

[2025-05-12 23:17:42] BŁĄD: Błąd predykcji: 'AnalysisGUI' object has no attribute 'update_status'
D:\python\veteye2\logs\training_log_2025-05-12.txt
Traceback (most recent call last):
  File "D:\python\veteye2\scripts\analysis_gui.py", line 160, in analyze_current_image
    self.update_status("Analiza zakończona pomyślnie")
AttributeError: 'AnalysisGUI' object has no attribute 'update_status'

[2025-05-12 23:22:26] BŁĄD: Błąd predykcji: 'AnalysisGUI' object has no attribute 'update_status'
D:\python\veteye2\logs\training_log_2025-05-12.txt
Traceback (most recent call last):
  File "D:\python\veteye2\scripts\analysis_gui.py", line 160, in analyze_current_image
    self.update_status("Analiza zakończona pomyślnie")
AttributeError: 'AnalysisGUI' object has no attribute 'update_status'

[2025-05-12 23:26:00] INFO: Używanie najnowszego modelu: D:\python\veteye2\checkpoints\usg_pregnancy_model_inceptionv3_380x380_final.keras
[2025-05-12 23:26:00] INFO: Uruchomiono interfejs analizy obrazów USG
[2025-05-12 23:26:00] INFO: Ładowanie modelu wykrywania ciąży: D:\python\veteye2\checkpoints\usg_pregnancy_model_inceptionv3_380x380_final.keras
[2025-05-12 23:26:02] SUKCES: Model wykrywania ciąży załadowany pomyślnie
[2025-05-12 23:26:02] BŁĄD: Nie znaleziono modelu szacowania dnia ciąży
D:\python\veteye2\logs\training_log_2025-05-12.txt
NoneType: None

[2025-05-12 23:28:45] INFO: Używanie najnowszego modelu: D:\python\veteye2\checkpoints\usg_pregnancy_model_inceptionv3_380x380_final.keras
[2025-05-12 23:28:45] INFO: Uruchomiono interfejs analizy obrazów USG
[2025-05-12 23:28:45] INFO: Ładowanie modelu wykrywania ciąży: D:\python\veteye2\checkpoints\usg_pregnancy_model_inceptionv3_380x380_final.keras
[2025-05-12 23:28:47] SUKCES: Model wykrywania ciąży załadowany pomyślnie
[2025-05-12 23:28:47] BŁĄD: Nie znaleziono modelu szacowania dnia ciąży
D:\python\veteye2\logs\training_log_2025-05-12.txt
NoneType: None

[2025-05-12 23:30:47] INFO: Używanie najnowszego modelu: D:\python\veteye2\checkpoints\usg_pregnancy_model_inceptionv3_380x380_final.keras
[2025-05-12 23:30:47] INFO: Uruchomiono interfejs analizy obrazów USG
[2025-05-12 23:30:47] INFO: Ładowanie modelu wykrywania ciąży: D:\python\veteye2\checkpoints\usg_pregnancy_model_inceptionv3_380x380_final.keras
[2025-05-12 23:30:49] SUKCES: Model wykrywania ciąży załadowany pomyślnie
[2025-05-12 23:30:49] BŁĄD: Nie znaleziono modelu szacowania dnia ciąży
D:\python\veteye2\logs\training_log_2025-05-12.txt
NoneType: None

[2025-05-12 23:34:05] INFO: Używanie najnowszego modelu: D:\python\veteye2\checkpoints\usg_pregnancy_model_inceptionv3_380x380_final.keras
[2025-05-12 23:34:05] INFO: Uruchomiono interfejs analizy obrazów USG
[2025-05-12 23:34:05] INFO: Ładowanie modelu wykrywania ciąży: D:\python\veteye2\checkpoints\usg_pregnancy_model_inceptionv3_380x380_final.keras
[2025-05-12 23:34:07] SUKCES: Model wykrywania ciąży załadowany pomyślnie
[2025-05-12 23:34:07] BŁĄD: Nie znaleziono modelu szacowania dnia ciąży
D:\python\veteye2\logs\training_log_2025-05-12.txt
NoneType: None

